Workbook

Sheet INFO TIENDAS
A1: CR | B1: ZONA | C1: DEPARTAMENTO | D1: MUN | E1: UPZ/COMUNA | F1: ESTRATO | G1: NAME | H1: ARRENDADOR | I1: TIPO DE LOCAL | J1: AREA | K1: VT | L1: ET | M1: FECHA APE | N1: DIA | O1: DIAS OP | P1: DIAS MES | Q1: MESOP | R1: TR15MIN | S1: Y | T1: X | U1: TRAFICO UM | V1: TRU6 | W1: TICKET UM | X1: TICKET U6M | Y1: VENTAS OUM | Z1: VU6M | AA1: CONTRIBUCION UM | AB1: CONTRIBUCION U6M | AC1: MARGEN UM | AD1: MARGEN U6M | AE1: RENTA | AF1: RU6M | AG1: %Batting | AH1: GENERADOR | AI1: ESTADO | AJ1: SEG26 | AK1: TIE26 | AL1: ME | AM1: COSTO M2 | AN1: TE | AO1: PTH
A2: 50WHX | B2: Centro Norte | C2: Distrito Capital | D2: Bogotá | E2: LOS CEDROS | F2: 5 | G2: 140 | H2: 0 | I2: Esquinero | J2: 177.38 | K2: 163 | L2: 3034 | M2: 0 | N2: 40514 | O2: 2 | P2: 30 | Q2: 31 | R2: 115 | S2: 4.7229 | T2: -74.044754 | U2: =_xlfn.XLOOKUP(A2,'BD UM'!A:A,'BD UM'!B:B) -> 22077 | V2: =_xlfn.XLOOKUP(A2,'BD U6M'!A:A,'BD U6M'!B:B) -> 18642.833 | W2: =_xlfn.XLOOKUP(A2,'BD UM'!A:A,'BD UM'!C:C) -> 11072.6 | X2: =_xlfn.XLOOKUP(A2,'BD U6M'!A:A,'BD U6M'!C:C) -> 11161.2 | Y2: =_xlfn.XLOOKUP(A2,'BD UM'!A:A,'BD UM'!D:D) -> 244450.15 | Z2: =_xlfn.XLOOKUP(A2,'BD U6M'!A:A,'BD U6M'!D:D) -> 208076.68 | AA2: =_xlfn.XLOOKUP(A2,'BD UM'!A:A,'BD UM'!E:E) -> 24670.567 | AB2: =_xlfn.XLOOKUP(A2,'BD U6M'!A:A,'BD U6M'!E:E) -> 14864.344 | AC2: =_xlfn.XLOOKUP(A2,'BD UM'!A:A,'BD UM'!F:F) -> 94683.375 | AD2: =_xlfn.XLOOKUP(A2,'BD U6M'!A:A,'BD U6M'!F:F) -> 77364.549 | AE2: =_xlfn.XLOOKUP(A2,'BD UM'!A:A,'BD UM'!G:G) -> 11964.614 | AF2: =_xlfn.XLOOKUP(A2,'BD U6M'!A:A,'BD U6M'!G:G) -> 11701.896 | AG2: =_xlfn.XLOOKUP(A2,'BD UM'!A:A,'BD UM'!H:H) -> 0 | AH2: BAJA DENSIDAD | AI2: ABIERTA | AJ2: BASE | AK2: TMCB | AL2: 232000 | AM2: 64.51 | AN2: PT | AO2: Alto
A3: 505ST | B3: Centro Sur | C3: Distrito Capital | D3: Bogotá | E3: LAS NIEVES | F3: 3 | G3: 724 | H3: CONSTRUCTORA COLPATRIA S.A.S | I3: Esquinero | J3: 111.57 | K3: 1589 | L3: 3640 | M3: 116 | N3: 45535 | O3: 31 | P3: 1 | Q3: 31 | R3: 24 | S3: 4.610195 | T3: -74.07075 | U3: =_xlfn.XLOOKUP(A3,'BD UM'!A:A,'BD UM'!B:B) -> 21529 | V3: =_xlfn.XLOOKUP(A3,'BD U6M'!A:A,'BD U6M'!B:B) -> 22400.667 | W3: =_xlfn.XLOOKUP(A3,'BD UM'!A:A,'BD UM'!C:C) -> 11000.6 | X3: =_xlfn.XLOOKUP(A3,'BD U6M'!A:A,'BD U6M'!C:C) -> 11195.9 | Y3: =_xlfn.XLOOKUP(A3,'BD UM'!A:A,'BD UM'!D:D) -> 236831.95 | Z3: =_xlfn.XLOOKUP(A3,'BD U6M'!A:A,'BD U6M'!D:D) -> 250796.24 | AA3: =_xlfn.XLOOKUP(A3,'BD UM'!A:A,'BD UM'!E:E) -> 23309.78 | AB3: =_xlfn.XLOOKUP(A3,'BD U6M'!A:A,'BD U6M'!E:E) -> 24111.698 | AC3: =_xlfn.XLOOKUP(A3,'BD UM'!A:A,'BD UM'!F:F) -> 86702.55 | AD3: =_xlfn.XLOOKUP(A3,'BD U6M'!A:A,'BD U6M'!F:F) -> 89892.042 | AE3: =_xlfn.XLOOKUP(A3,'BD UM'!A:A,'BD UM'!G:G) -> 10652.709 | AF3: =_xlfn.XLOOKUP(A3,'BD U6M'!A:A,'BD U6M'!G:G) -> 10468.454 | AG3: =_xlfn.XLOOKUP(A3,'BD UM'!A:A,'BD UM'!H:H) -> 0 | AH3: ADMINISTRATIVO | AI3: ABIERTA | AJ3: BASE | AK3: EXP 2024 | AL3: 232000 | AM3: 92.69 | AN3: Bosque Izquierdo | AO3: Medio
A4: 50QK2 | B4: Centro Sur | C4: Distrito Capital | D4: Bogotá | E4: CIUDAD JARDIN | F4: 3 | G4: 1ero De Mayo | H4: 0 | I4: Esquinero | J4: 83.9 | K4: 537 | L4: 142 | M4: 186 | N4: 43740 | O4: 2 | P4: 30 | Q4: 31 | R4: 83 | S4: 4.576091 | T4: -74.094651 | U4: =_xlfn.XLOOKUP(A4,'BD UM'!A:A,'BD UM'!B:B) -> 24710 | V4: =_xlfn.XLOOKUP(A4,'BD U6M'!A:A,'BD U6M'!B:B) -> 26219.833 | W4: =_xlfn.XLOOKUP(A4,'BD UM'!A:A,'BD UM'!C:C) -> 11952.2 | X4: =_xlfn.XLOOKUP(A4,'BD U6M'!A:A,'BD U6M'!C:C) -> 12043.8 | Y4: =_xlfn.XLOOKUP(A4,'BD UM'!A:A,'BD UM'!D:D) -> 295339.88 | Z4: =_xlfn.XLOOKUP(A4,'BD U6M'!A:A,'BD U6M'!D:D) -> 315786.29 | AA4: =_xlfn.XLOOKUP(A4,'BD UM'!A:A,'BD UM'!E:E) -> 29877.54 | AB4: =_xlfn.XLOOKUP(A4,'BD U6M'!A:A,'BD U6M'!E:E) -> 34274.564 | AC4: =_xlfn.XLOOKUP(A4,'BD UM'!A:A,'BD UM'!F:F) -> 95950.726 | AD4: =_xlfn.XLOOKUP(A4,'BD U6M'!A:A,'BD U6M'!F:F) -> 104090.9 | AE4: =_xlfn.XLOOKUP(A4,'BD UM'!A:A,'BD UM'!G:G) -> 8067.591 | AF4: =_xlfn.XLOOKUP(A4,'BD U6M'!A:A,'BD U6M'!G:G) -> 7824.8097 | AG4: =_xlfn.XLOOKUP(A4,'BD UM'!A:A,'BD UM'!H:H) -> 0 | AH4: COMERCIO/SERVICIO | AI4: ABIERTA | AJ4: BASE | AK4: TMCB | AL4: 232000 | AM4: 91.49 | AN4: Quiroga | AO4: Medio
A5: 50HQ9 | B5: Centro Sur | C5: Distrito Capital | D5: Bogotá | E5: PARDO RUBIO | F5: 4 | G5: 7 Estorias | H5: 0 | I5: Esquinero | J5: 128.02 | K5: 2789 | L5: 1350 | M5: 139 | N5: 46078 | O5: 25 | P5: 4 | Q5: 28 | R5: 6 | S5: 6.249603 | T5: -75.588874 | U5: =_xlfn.XLOOKUP(A5,'BD UM'!A:A,'BD UM'!B:B) -> 16492 | V5: =_xlfn.XLOOKUP(A5,'BD U6M'!A:A,'BD U6M'!B:B) -> 14178.333 | W5: =_xlfn.XLOOKUP(A5,'BD UM'!A:A,'BD UM'!C:C) -> 11515.4 | X5: =_xlfn.XLOOKUP(A5,'BD U6M'!A:A,'BD U6M'!C:C) -> 11523.2 | Y5: =_xlfn.XLOOKUP(A5,'BD UM'!A:A,'BD UM'!D:D) -> 189911.95 | Z5: =_xlfn.XLOOKUP(A5,'BD U6M'!A:A,'BD U6M'!D:D) -> 163380.17 | AA5: =_xlfn.XLOOKUP(A5,'BD UM'!A:A,'BD UM'!E:E) -> 13610.537 | AB5: =_xlfn.XLOOKUP(A5,'BD U6M'!A:A,'BD U6M'!E:E) -> 7529.342 | AC5: =_xlfn.XLOOKUP(A5,'BD UM'!A:A,'BD UM'!F:F) -> 71073.664 | AD5: =_xlfn.XLOOKUP(A5,'BD U6M'!A:A,'BD U6M'!F:F) -> 59571.772 | AE5: =_xlfn.XLOOKUP(A5,'BD UM'!A:A,'BD UM'!G:G) -> 9877.52 | AF5: =_xlfn.XLOOKUP(A5,'BD U6M'!A:A,'BD U6M'!G:G) -> 8465.2449 | AG5: =_xlfn.XLOOKUP(A5,'BD UM'!A:A,'BD UM'!H:H) -> 1.3425 | AH5: ND | AI5: ABIERTA | AJ5: BASE | AK5: EXP 2026 | AL5: 204160 | AM5: 77.16 | AN5: Septima 49 | AO5: Medio
A6: 50VEG | B6: Centro Norte | C6: Distrito Capital | D6: Bogotá | E6: CHICO LAGO | F6: 4 | G6: 72 Caracas | H6: TAQ INVERSIONES S.A.S | I6: Esquinero | J6: 125.91 | K6: 560 | L6: 2330 | M6: 235 | N6: 45899 | O6: 30 | P6: 2 | Q6: 31 | R6: 12 | S6: 4.658777 | T6: -74.061517 | U6: =_xlfn.XLOOKUP(A6,'BD UM'!A:A,'BD UM'!B:B) -> 19258 | V6: =_xlfn.XLOOKUP(A6,'BD U6M'!A:A,'BD U6M'!B:B) -> 15677.833 | W6: =_xlfn.XLOOKUP(A6,'BD UM'!A:A,'BD UM'!C:C) -> 10212.9 | X6: =_xlfn.XLOOKUP(A6,'BD U6M'!A:A,'BD U6M'!C:C) -> 10403.3 | Y6: =_xlfn.XLOOKUP(A6,'BD UM'!A:A,'BD UM'!D:D) -> 196680.59 | Z6: =_xlfn.XLOOKUP(A6,'BD U6M'!A:A,'BD U6M'!D:D) -> 163101.26 | AA6: =_xlfn.XLOOKUP(A6,'BD UM'!A:A,'BD UM'!E:E) -> 6743.534 | AB6: =_xlfn.XLOOKUP(A6,'BD U6M'!A:A,'BD U6M'!E:E) -> -2707.8947 | AC6: =_xlfn.XLOOKUP(A6,'BD UM'!A:A,'BD UM'!F:F) -> 73753.755 | AD6: =_xlfn.XLOOKUP(A6,'BD U6M'!A:A,'BD U6M'!F:F) -> 58330.5 | AE6: =_xlfn.XLOOKUP(A6,'BD UM'!A:A,'BD UM'!G:G) -> 19286.25 | AF6: =_xlfn.XLOOKUP(A6,'BD U6M'!A:A,'BD U6M'!G:G) -> 18805.255 | AG6: =_xlfn.XLOOKUP(A6,'BD UM'!A:A,'BD UM'!H:H) -> 1.0328 | AH6: COMERCIO/SERVICIO | AI6: ABIERTA | AJ6: BASE | AK6: EXP 2025 | AL6: 232000 | AM6: 146.93 | AN6: 1ero De Mayo | AO6: Medio
A7: 50EXM | B7: Centro Sur | C7: Distrito Capital | D7: Bogotá | E7: CASTILLA | F7: 3 | G7: 72 Castilla | H7: 0 | I7: Esquinero | J7: 146.43 | K7: 1343 | L7: 375 | M7: 0 | N7: 44672 | O7: 21 | P7: 10 | Q7: 30 | R7: 52 | S7: 4.639826 | T7: -74.137131 | U7: =_xlfn.XLOOKUP(A7,'BD UM'!A:A,'BD UM'!B:B) -> 15085 | V7: =_xlfn.XLOOKUP(A7,'BD U6M'!A:A,'BD U6M'!B:B) -> 14927.5 | W7: =_xlfn.XLOOKUP(A7,'BD UM'!A:A,'BD UM'!C:C) -> 13272.9 | X7: =_xlfn.XLOOKUP(A7,'BD U6M'!A:A,'BD U6M'!C:C) -> 14024.1 | Y7: =_xlfn.XLOOKUP(A7,'BD UM'!A:A,'BD UM'!D:D) -> 200221.17 | Z7: =_xlfn.XLOOKUP(A7,'BD U6M'!A:A,'BD U6M'!D:D) -> 209344.71 | AA7: =_xlfn.XLOOKUP(A7,'BD UM'!A:A,'BD UM'!E:E) -> 13884.992 | AB7: =_xlfn.XLOOKUP(A7,'BD U6M'!A:A,'BD U6M'!E:E) -> 12789.462 | AC7: =_xlfn.XLOOKUP(A7,'BD UM'!A:A,'BD UM'!F:F) -> 66934.827 | AD7: =_xlfn.XLOOKUP(A7,'BD U6M'!A:A,'BD U6M'!F:F) -> 69195.44 | AE7: =_xlfn.XLOOKUP(A7,'BD UM'!A:A,'BD UM'!G:G) -> 9567.458 | AF7: =_xlfn.XLOOKUP(A7,'BD U6M'!A:A,'BD U6M'!G:G) -> 9664.2761 | AG7: =_xlfn.XLOOKUP(A7,'BD UM'!A:A,'BD UM'!H:H) -> 0 | AH7: BAJA DENSIDAD | AI7: ABIERTA | AJ7: HOGAR | AK7: TMCB | AL7: 241405 | AM7: 65.33 | AN7: Britania | AO7: Medio
A8: 50WLE | B8: Centro Sur | C8: Distrito Capital | D8: Bogotá | E8: KENNEDY CENTRAL | F8: 3 | G8: 73 Kennedy | H8: 0 | I8: Esquinero | J8: 99.8 | K8: 1837 | L8: 1249 | M8: 0 | N8: 44587 | O8: 26 | P8: 6 | Q8: 31 | R8: 55 | S8: 4.621015 | T8: -74.147364 | U8: =_xlfn.XLOOKUP(A8,'BD UM'!A:A,'BD UM'!B:B) -> 15770 | V8: =_xlfn.XLOOKUP(A8,'BD U6M'!A:A,'BD U6M'!B:B) -> 16554.833 | W8: =_xlfn.XLOOKUP(A8,'BD UM'!A:A,'BD UM'!C:C) -> 12160.2 | X8: =_xlfn.XLOOKUP(A8,'BD U6M'!A:A,'BD U6M'!C:C) -> 12236.3 | Y8: =_xlfn.XLOOKUP(A8,'BD UM'!A:A,'BD UM'!D:D) -> 191765.95 | Z8: =_xlfn.XLOOKUP(A8,'BD U6M'!A:A,'BD U6M'!D:D) -> 202569.39 | AA8: =_xlfn.XLOOKUP(A8,'BD UM'!A:A,'BD UM'!E:E) -> 6919.84 | AB8: =_xlfn.XLOOKUP(A8,'BD U6M'!A:A,'BD U6M'!E:E) -> 11253.276 | AC8: =_xlfn.XLOOKUP(A8,'BD UM'!A:A,'BD UM'!F:F) -> 59452.32 | AD8: =_xlfn.XLOOKUP(A8,'BD U6M'!A:A,'BD U6M'!F:F) -> 62913.102 | AE8: =_xlfn.XLOOKUP(A8,'BD UM'!A:A,'BD UM'!G:G) -> 8928.005 | AF8: =_xlfn.XLOOKUP(A8,'BD U6M'!A:A,'BD U6M'!G:G) -> 9021.956 | AG8: =_xlfn.XLOOKUP(A8,'BD UM'!A:A,'BD UM'!H:H) -> 0 | AH8: BAJA DENSIDAD | AI8: ABIERTA | AJ8: HOGAR | AK8: TMCB | AL8: 241405 | AM8: 89.46 | AN8: Kennedy Central | AO8: Medio
A9: 50JA1 | B9: Centro Sur | C9: Distrito Capital | D9: Bogotá | E9: KENNEDY CENTRAL | F9: 3 | G9: 78 Kennedy | H9: 0 | I9: Esquinero | J9: 99.5 | K9: 1566 | L9: 1357 | M9: 0 | N9: 44684 | O9: 3 | P9: 29 | Q9: 31 | R9: 51 | S9: 4.622262 | T9: -74.149932 | U9: =_xlfn.XLOOKUP(A9,'BD UM'!A:A,'BD UM'!B:B) -> 16851 | V9: =_xlfn.XLOOKUP(A9,'BD U6M'!A:A,'BD U6M'!B:B) -> 15549 | W9: =_xlfn.XLOOKUP(A9,'BD UM'!A:A,'BD UM'!C:C) -> 10348.5 | X9: =_xlfn.XLOOKUP(A9,'BD U6M'!A:A,'BD U6M'!C:C) -> 10893 | Y9: =_xlfn.XLOOKUP(A9,'BD UM'!A:A,'BD UM'!D:D) -> 174382.02 | Z9: =_xlfn.XLOOKUP(A9,'BD U6M'!A:A,'BD U6M'!D:D) -> 169374.89 | AA9: =_xlfn.XLOOKUP(A9,'BD UM'!A:A,'BD UM'!E:E) -> 6278.494 | AB9: =_xlfn.XLOOKUP(A9,'BD U6M'!A:A,'BD U6M'!E:E) -> 5938.4532 | AC9: =_xlfn.XLOOKUP(A9,'BD UM'!A:A,'BD UM'!F:F) -> 58383.102 | AD9: =_xlfn.XLOOKUP(A9,'BD U6M'!A:A,'BD U6M'!F:F) -> 57350.701 | AE9: =_xlfn.XLOOKUP(A9,'BD UM'!A:A,'BD UM'!G:G) -> 8789.815 | AF9: =_xlfn.XLOOKUP(A9,'BD U6M'!A:A,'BD U6M'!G:G) -> 8908.3433 | AG9: =_xlfn.XLOOKUP(A9,'BD UM'!A:A,'BD UM'!H:H) -> 0 | AH9: SALUD | AI9: ABIERTA | AJ9: BASE | AK9: EXP 2024 | AL9: 204160 | AM9: 55.43 | AN9: Gonzalez Valencia | AO9: Alto
A10: 505TQ | B10: Centro Sur | C10: Cundinamarca | D10: Girardot | E10: NORTE | F10: 3 | G10: Acacias | H10: 0 | I10: Esquinero | J10: 121.8 | K10: 770 | L10: 675 | M10: 36 | N10: 45259 | O10: 29 | P10: 2 | Q10: 30 | R10: 33 | S10: 4.307396 | T10: -74.803587 | U10: =_xlfn.XLOOKUP(A10,'BD UM'!A:A,'BD UM'!B:B) -> 18516 | V10: =_xlfn.XLOOKUP(A10,'BD U6M'!A:A,'BD U6M'!B:B) -> 17323.5 | W10: =_xlfn.XLOOKUP(A10,'BD UM'!A:A,'BD UM'!C:C) -> 14178.2 | X10: =_xlfn.XLOOKUP(A10,'BD U6M'!A:A,'BD U6M'!C:C) -> 14137.4 | Y10: =_xlfn.XLOOKUP(A10,'BD UM'!A:A,'BD UM'!D:D) -> 262523.89 | Z10: =_xlfn.XLOOKUP(A10,'BD U6M'!A:A,'BD U6M'!D:D) -> 244908.63 | AA10: =_xlfn.XLOOKUP(A10,'BD UM'!A:A,'BD UM'!E:E) -> 21691.861 | AB10: =_xlfn.XLOOKUP(A10,'BD U6M'!A:A,'BD U6M'!E:E) -> 19392.74 | AC10: =_xlfn.XLOOKUP(A10,'BD UM'!A:A,'BD UM'!F:F) -> 84571.373 | AD10: =_xlfn.XLOOKUP(A10,'BD U6M'!A:A,'BD U6M'!F:F) -> 79228.526 | AE10: =_xlfn.XLOOKUP(A10,'BD UM'!A:A,'BD UM'!G:G) -> 5000 | AF10: =_xlfn.XLOOKUP(A10,'BD U6M'!A:A,'BD U6M'!G:G) -> 5061.014 | AG10: =_xlfn.XLOOKUP(A10,'BD UM'!A:A,'BD UM'!H:H) -> 0 | AH10: COMERCIO/SERVICIO | AI10: ABIERTA | AJ10: BASE | AK10: TMCB | AL10: 232000 | AM10: 41.05 | AN10: Uan Sur | AO10: Bajo
A11: 509BS | B11: Centro Norte | C11: Distrito Capital | D11: Bogotá | E11: COUNTRY CLUB | F11: 5 | G11: Acomedica 2 | H11: 0 | I11: Medianero | J11: 169.13 | K11: 650 | L11: 1848 | M11: 0 | N11: 44679 | O11: 28 | P11: 3 | Q11: 30 | R11: 52 | S11: 4.706164 | T11: -74.050061 | U11: =_xlfn.XLOOKUP(A11,'BD UM'!A:A,'BD UM'!B:B) -> 17060 | V11: =_xlfn.XLOOKUP(A11,'BD U6M'!A:A,'BD U6M'!B:B) -> 17249.5 | W11: =_xlfn.XLOOKUP(A11,'BD UM'!A:A,'BD UM'!C:C) -> 10898.4 | X11: =_xlfn.XLOOKUP(A11,'BD U6M'!A:A,'BD U6M'!C:C) -> 10911.8 | Y11: =_xlfn.XLOOKUP(A11,'BD UM'!A:A,'BD UM'!D:D) -> 185927.1 | Z11: =_xlfn.XLOOKUP(A11,'BD U6M'!A:A,'BD U6M'!D:D) -> 188223.76 | AA11: =_xlfn.XLOOKUP(A11,'BD UM'!A:A,'BD UM'!E:E) -> 12813.622 | AB11: =_xlfn.XLOOKUP(A11,'BD U6M'!A:A,'BD U6M'!E:E) -> 13611.432 | AC11: =_xlfn.XLOOKUP(A11,'BD UM'!A:A,'BD UM'!F:F) -> 81384.913 | AD11: =_xlfn.XLOOKUP(A11,'BD U6M'!A:A,'BD U6M'!F:F) -> 82267.277 | AE11: =_xlfn.XLOOKUP(A11,'BD UM'!A:A,'BD UM'!G:G) -> 21185.086 | AF11: =_xlfn.XLOOKUP(A11,'BD U6M'!A:A,'BD U6M'!G:G) -> 21300.101 | AG11: =_xlfn.XLOOKUP(A11,'BD UM'!A:A,'BD UM'!H:H) -> 0 | AH11: SALUD | AI11: ABIERTA | AJ11: BASE | AK11: TMCB | AL11: 232000 | AM11: 66.6 | AN11: Chicamocha | AO11: Medio
A12: 502B0 | B12: Occidente | C12: Risaralda | D12: Dosquebradas | E12: COMUNA 10 | F12: 3 | G12: Acuarela | H12: 0 | I12: Esquinero | J12: 126.54 | K12: 1914 | L12: 150 | M12: 98 | N12: 45443 | O12: 31 | P12: 1 | Q12: 31 | R12: 27 | S12: 4.851488 | T12: -75.662514 | U12: =_xlfn.XLOOKUP(A12,'BD UM'!A:A,'BD UM'!B:B) -> 18230 | V12: =_xlfn.XLOOKUP(A12,'BD U6M'!A:A,'BD U6M'!B:B) -> 17241.667 | W12: =_xlfn.XLOOKUP(A12,'BD UM'!A:A,'BD UM'!C:C) -> 16856.1 | X12: =_xlfn.XLOOKUP(A12,'BD U6M'!A:A,'BD U6M'!C:C) -> 15371.1 | Y12: =_xlfn.XLOOKUP(A12,'BD UM'!A:A,'BD UM'!D:D) -> 307286.2 | Z12: =_xlfn.XLOOKUP(A12,'BD U6M'!A:A,'BD U6M'!D:D) -> 265023.9 | AA12: =_xlfn.XLOOKUP(A12,'BD UM'!A:A,'BD UM'!E:E) -> 47419.103 | AB12: =_xlfn.XLOOKUP(A12,'BD U6M'!A:A,'BD U6M'!E:E) -> 37186.756 | AC12: =_xlfn.XLOOKUP(A12,'BD UM'!A:A,'BD UM'!F:F) -> 114466.78 | AD12: =_xlfn.XLOOKUP(A12,'BD U6M'!A:A,'BD U6M'!F:F) -> 97010.258 | AE12: =_xlfn.XLOOKUP(A12,'BD UM'!A:A,'BD UM'!G:G) -> 4493.149 | AF12: =_xlfn.XLOOKUP(A12,'BD U6M'!A:A,'BD U6M'!G:G) -> 4523.917 | AG12: =_xlfn.XLOOKUP(A12,'BD UM'!A:A,'BD UM'!H:H) -> 0 | AH12: COMERCIO/SERVICIO | AI12: ABIERTA | AJ12: BASE | AK12: TMCB | AL12: 232000 | AM12: 35.51 | AN12: TC | AO12: Alto
A13: 50IHY | B13: Occidente | C13: Valle del Cauca | D13: Cali | E13: COMUNA 19 | F13: 5 | G13: Afe Refugio | H13: SPORT SALUD CENTRO MÉDICO DEPORTIVO SAS | I13: Esquinero | J13: 120 | K13: 2 | L13: 406 | M13: 81 | N13: 45495 | O13: 22 | P13: 10 | Q13: 31 | R13: 25 | S13: 3.39805 | T13: -76.549917 | U13: =_xlfn.XLOOKUP(A13,'BD UM'!A:A,'BD UM'!B:B) -> 15763 | V13: =_xlfn.XLOOKUP(A13,'BD U6M'!A:A,'BD U6M'!B:B) -> 18375.833 | W13: =_xlfn.XLOOKUP(A13,'BD UM'!A:A,'BD UM'!C:C) -> 12853.6 | X13: =_xlfn.XLOOKUP(A13,'BD U6M'!A:A,'BD U6M'!C:C) -> 12581.2 | Y13: =_xlfn.XLOOKUP(A13,'BD UM'!A:A,'BD UM'!D:D) -> 202611.65 | Z13: =_xlfn.XLOOKUP(A13,'BD U6M'!A:A,'BD U6M'!D:D) -> 231190.35 | AA13: =_xlfn.XLOOKUP(A13,'BD UM'!A:A,'BD UM'!E:E) -> -2863.765 | AB13: =_xlfn.XLOOKUP(A13,'BD U6M'!A:A,'BD U6M'!E:E) -> 15395.307 | AC13: =_xlfn.XLOOKUP(A13,'BD UM'!A:A,'BD UM'!F:F) -> 81946.027 | AD13: =_xlfn.XLOOKUP(A13,'BD U6M'!A:A,'BD U6M'!F:F) -> 84952.666 | AE13: =_xlfn.XLOOKUP(A13,'BD UM'!A:A,'BD UM'!G:G) -> 11056.52 | AF13: =_xlfn.XLOOKUP(A13,'BD U6M'!A:A,'BD U6M'!G:G) -> 10806.189 | AG13: =_xlfn.XLOOKUP(A13,'BD UM'!A:A,'BD UM'!H:H) -> 0 | AH13: COMERCIO/SERVICIO | AI13: ABIERTA | AJ13: BASE | AK13: EXP 2024 | AL13: 232000 | AM13: 87.67 | AN13: Cedritos | AO13: Medio
A14: 505DL | B14: Oriente | C14: Santander | D14: Bucaramanga | E14: ORIENTAL | F14: 4 | G14: Agustin | H14: 0 | I14: Esquinero | J14: 76.05 | K14: 2 | L14: 2 | M14: 0 | N14: 43637 | O14: 21 | P14: 10 | Q14: 30 | R14: 86 | S14: 6.1474794 | T14: -75.616317 | U14: =_xlfn.XLOOKUP(A14,'BD UM'!A:A,'BD UM'!B:B) -> 16104 | V14: =_xlfn.XLOOKUP(A14,'BD U6M'!A:A,'BD U6M'!B:B) -> 15640 | W14: =_xlfn.XLOOKUP(A14,'BD UM'!A:A,'BD UM'!C:C) -> 9686.7 | X14: =_xlfn.XLOOKUP(A14,'BD U6M'!A:A,'BD U6M'!C:C) -> 10059.9 | Y14: =_xlfn.XLOOKUP(A14,'BD UM'!A:A,'BD UM'!D:D) -> 155994.16 | Z14: =_xlfn.XLOOKUP(A14,'BD U6M'!A:A,'BD U6M'!D:D) -> 157336.07 | AA14: =_xlfn.XLOOKUP(A14,'BD UM'!A:A,'BD UM'!E:E) -> 1763.756 | AB14: =_xlfn.XLOOKUP(A14,'BD U6M'!A:A,'BD U6M'!E:E) -> 9139.4587 | AC14: =_xlfn.XLOOKUP(A14,'BD UM'!A:A,'BD UM'!F:F) -> 57080.948 | AD14: =_xlfn.XLOOKUP(A14,'BD U6M'!A:A,'BD U6M'!F:F) -> 57716.038 | AE14: =_xlfn.XLOOKUP(A14,'BD UM'!A:A,'BD UM'!G:G) -> 4814.108 | AF14: =_xlfn.XLOOKUP(A14,'BD U6M'!A:A,'BD U6M'!G:G) -> 4798.8428 | AG14: =_xlfn.XLOOKUP(A14,'BD UM'!A:A,'BD UM'!H:H) -> 0 | AH14: COMERCIO/SERVICIO | AI14: ABIERTA | AJ14: RECESO | AK14: TMCB | AL14: 232000 | AM14: 63.09 | AN14: PT | AO14: Medio
A15: 50T5A | B15: Centro Norte | C15: Boyacá | D15: Tunja | E15: NORTE (1) | F15: 4 | G15: Alameda De Unicentro | H15: 0 | I15: Esquinero | J15: 148 | K15: 1 | L15: 474 | M15: 71 | N15: 45412 | O15: 30 | P15: 1 | Q15: 30 | R15: 28 | S15: 5.5479207 | T15: -73.346477 | U15: =_xlfn.XLOOKUP(A15,'BD UM'!A:A,'BD UM'!B:B) -> 15656 | V15: =_xlfn.XLOOKUP(A15,'BD U6M'!A:A,'BD U6M'!B:B) -> 14237.5 | W15: =_xlfn.XLOOKUP(A15,'BD UM'!A:A,'BD UM'!C:C) -> 12949.7 | X15: =_xlfn.XLOOKUP(A15,'BD U6M'!A:A,'BD U6M'!C:C) -> 13545.4 | Y15: =_xlfn.XLOOKUP(A15,'BD UM'!A:A,'BD UM'!D:D) -> 202740.21 | Z15: =_xlfn.XLOOKUP(A15,'BD U6M'!A:A,'BD U6M'!D:D) -> 192852.15 | AA15: =_xlfn.XLOOKUP(A15,'BD UM'!A:A,'BD UM'!E:E) -> 13181.916 | AB15: =_xlfn.XLOOKUP(A15,'BD U6M'!A:A,'BD U6M'!E:E) -> 10651.653 | AC15: =_xlfn.XLOOKUP(A15,'BD UM'!A:A,'BD UM'!F:F) -> 71107.855 | AD15: =_xlfn.XLOOKUP(A15,'BD U6M'!A:A,'BD U6M'!F:F) -> 68661.933 | AE15: =_xlfn.XLOOKUP(A15,'BD UM'!A:A,'BD UM'!G:G) -> 9151.066 | AF15: =_xlfn.XLOOKUP(A15,'BD U6M'!A:A,'BD U6M'!G:G) -> 9164.1217 | AG15: =_xlfn.XLOOKUP(A15,'BD UM'!A:A,'BD UM'!H:H) -> 0 | AH15: EDUCACION | AI15: ABIERTA | AJ15: BASE | AK15: TMCB | AL15: 232000 | AM15: 61.83 | AN15: Portal Javeriana | AO15: Medio
A16: 50UPU | B16: Centro Sur | C16: Distrito Capital | D16: Bogotá | E16: BOYACA REAL | F16: 3 | G16: Alamos 90 | H16: MAYRA ALEJANDRA ARIZA JIMENEZ y MIGUEL ANGEL ARIZA JIMENEZ | I16: Esquinero | J16: 98.6 | K16: 3149 | L16: 105 | M16: 106 | N16: 45770 | O16: 23 | P16: 8 | Q16: 30 | R16: 16 | S16: 4.695583 | T16: -74.110236 | U16: =_xlfn.XLOOKUP(A16,'BD UM'!A:A,'BD UM'!B:B) -> 17621 | V16: =_xlfn.XLOOKUP(A16,'BD U6M'!A:A,'BD U6M'!B:B) -> 17516.667 | W16: =_xlfn.XLOOKUP(A16,'BD UM'!A:A,'BD UM'!C:C) -> 12035.9 | X16: =_xlfn.XLOOKUP(A16,'BD U6M'!A:A,'BD U6M'!C:C) -> 11979.1 | Y16: =_xlfn.XLOOKUP(A16,'BD UM'!A:A,'BD UM'!D:D) -> 212085.27 | Z16: =_xlfn.XLOOKUP(A16,'BD U6M'!A:A,'BD U6M'!D:D) -> 209833.43 | AA16: =_xlfn.XLOOKUP(A16,'BD UM'!A:A,'BD UM'!E:E) -> 14067.499 | AB16: =_xlfn.XLOOKUP(A16,'BD U6M'!A:A,'BD U6M'!E:E) -> 13948.008 | AC16: =_xlfn.XLOOKUP(A16,'BD UM'!A:A,'BD UM'!F:F) -> 66113.363 | AD16: =_xlfn.XLOOKUP(A16,'BD U6M'!A:A,'BD U6M'!F:F) -> 65631.033 | AE16: =_xlfn.XLOOKUP(A16,'BD UM'!A:A,'BD UM'!G:G) -> 7882.5 | AF16: =_xlfn.XLOOKUP(A16,'BD U6M'!A:A,'BD U6M'!G:G) -> 7902.5332 | AG16: =_xlfn.XLOOKUP(A16,'BD UM'!A:A,'BD UM'!H:H) -> 1.4606 | AH16: ALTA DENSIDAD | AI16: ABIERTA | AJ16: HOGAR | AK16: EXP 2025 | AL16: 241405 | AM16: 79.95 | AN16: Trinidad Galan | AO16: Bajo
A17: 50FZH | B17: Centro Sur | C17: Distrito Capital | D17: Bogotá | E17: ALAMOS | F17: 3 | G17: Alamos Industrial | H17: 0 | I17: Esquinero | J17: 157.95 | K17: 0 | L17: 5400 | M17: 52 | N17: 45168 | O17: 30 | P17: 2 | Q17: 31 | R17: 36 | S17: 4.6900555 | T17: -74.117545 | U17: =_xlfn.XLOOKUP(A17,'BD UM'!A:A,'BD UM'!B:B) -> 16578 | V17: =_xlfn.XLOOKUP(A17,'BD U6M'!A:A,'BD U6M'!B:B) -> 17073.833 | W17: =_xlfn.XLOOKUP(A17,'BD UM'!A:A,'BD UM'!C:C) -> 11756.7 | X17: =_xlfn.XLOOKUP(A17,'BD U6M'!A:A,'BD U6M'!C:C) -> 10774.8 | Y17: =_xlfn.XLOOKUP(A17,'BD UM'!A:A,'BD UM'!D:D) -> 194901.99 | Z17: =_xlfn.XLOOKUP(A17,'BD U6M'!A:A,'BD U6M'!D:D) -> 183967.49 | AA17: =_xlfn.XLOOKUP(A17,'BD UM'!A:A,'BD UM'!E:E) -> 16836.768 | AB17: =_xlfn.XLOOKUP(A17,'BD U6M'!A:A,'BD U6M'!E:E) -> 13801.752 | AC17: =_xlfn.XLOOKUP(A17,'BD UM'!A:A,'BD UM'!F:F) -> 69852.446 | AD17: =_xlfn.XLOOKUP(A17,'BD U6M'!A:A,'BD U6M'!F:F) -> 67972.798 | AE17: =_xlfn.XLOOKUP(A17,'BD UM'!A:A,'BD UM'!G:G) -> 9786.877 | AF17: =_xlfn.XLOOKUP(A17,'BD U6M'!A:A,'BD U6M'!G:G) -> 9530.5266 | AG17: =_xlfn.XLOOKUP(A17,'BD UM'!A:A,'BD UM'!H:H) -> 0 | AH17: ADMINISTRATIVO | AI17: ABIERTA | AJ17: RECESO | AK17: TMCB | AL17: 204160 | AM17: 58.96 | AN17: Zona Franca | AO17: Medio
A18: 50IOP | B18: Centro Norte | C18: Distrito Capital | D18: Bogotá | E18: EL PRADO | F18: 3 | G18: Alcala | H18: 0 | I18: Esquinero | J18: 112.03 | K18: 1080 | L18: 1240 | M18: 138 | N18: 45199 | O18: 30 | P18: 1 | Q18: 30 | R18: 35 | S18: 4.7228338 | T18: -74.051648 | U18: =_xlfn.XLOOKUP(A18,'BD UM'!A:A,'BD UM'!B:B) -> 17087 | V18: =_xlfn.XLOOKUP(A18,'BD U6M'!A:A,'BD U6M'!B:B) -> 16886.167 | W18: =_xlfn.XLOOKUP(A18,'BD UM'!A:A,'BD UM'!C:C) -> 11199.9 | X18: =_xlfn.XLOOKUP(A18,'BD U6M'!A:A,'BD U6M'!C:C) -> 11410.1 | Y18: =_xlfn.XLOOKUP(A18,'BD UM'!A:A,'BD UM'!D:D) -> 191372.06 | Z18: =_xlfn.XLOOKUP(A18,'BD U6M'!A:A,'BD U6M'!D:D) -> 192673.52 | AA18: =_xlfn.XLOOKUP(A18,'BD UM'!A:A,'BD UM'!E:E) -> 10507.289 | AB18: =_xlfn.XLOOKUP(A18,'BD U6M'!A:A,'BD U6M'!E:E) -> 9823.5799 | AC18: =_xlfn.XLOOKUP(A18,'BD UM'!A:A,'BD UM'!F:F) -> 67267.439 | AD18: =_xlfn.XLOOKUP(A18,'BD U6M'!A:A,'BD U6M'!F:F) -> 66433.983 | AE18: =_xlfn.XLOOKUP(A18,'BD UM'!A:A,'BD UM'!G:G) -> 7185.16 | AF18: =_xlfn.XLOOKUP(A18,'BD U6M'!A:A,'BD U6M'!G:G) -> 7264.4969 | AG18: =_xlfn.XLOOKUP(A18,'BD UM'!A:A,'BD UM'!H:H) -> 0 | AH18: COMERCIO/SERVICIO | AI18: ABIERTA | AJ18: BASE | AK18: TMCB | AL18: 232000 | AM18: 64.13 | AN18: Rionegro | AO18: Medio
A19: 503Z7 | B19: Oriente | C19: Santander | D19: Piedecuesta | E19: PIEDECUESTA | F19: 6 | G19: Aldea Comercial | H19: 0 | I19: Medianero | J19: 95.42 | K19: 1652 | L19: 489 | M19: 216 | N19: 45377 | O19: 26 | P19: 6 | Q19: 31 | R19: 29 | S19: 7.0236593 | T19: -73.082625 | U19: =_xlfn.XLOOKUP(A19,'BD UM'!A:A,'BD UM'!B:B) -> 10617 | V19: =_xlfn.XLOOKUP(A19,'BD U6M'!A:A,'BD U6M'!B:B) -> 9694 | W19: =_xlfn.XLOOKUP(A19,'BD UM'!A:A,'BD UM'!C:C) -> 13453.8 | X19: =_xlfn.XLOOKUP(A19,'BD U6M'!A:A,'BD U6M'!C:C) -> 14751.5 | Y19: =_xlfn.XLOOKUP(A19,'BD UM'!A:A,'BD UM'!D:D) -> 142838.67 | Z19: =_xlfn.XLOOKUP(A19,'BD U6M'!A:A,'BD U6M'!D:D) -> 143000.93 | AA19: =_xlfn.XLOOKUP(A19,'BD UM'!A:A,'BD UM'!E:E) -> 5666.403 | AB19: =_xlfn.XLOOKUP(A19,'BD U6M'!A:A,'BD U6M'!E:E) -> 4523.284 | AC19: =_xlfn.XLOOKUP(A19,'BD UM'!A:A,'BD UM'!F:F) -> 55731.84 | AD19: =_xlfn.XLOOKUP(A19,'BD U6M'!A:A,'BD U6M'!F:F) -> 57017.756 | AE19: =_xlfn.XLOOKUP(A19,'BD UM'!A:A,'BD UM'!G:G) -> 8077.396 | AF19: =_xlfn.XLOOKUP(A19,'BD U6M'!A:A,'BD U6M'!G:G) -> 8215.5747 | AG19: =_xlfn.XLOOKUP(A19,'BD UM'!A:A,'BD UM'!H:H) -> 0 | AH19: BAJA DENSIDAD | AI19: ABIERTA | AJ19: HOGAR | AK19: TMCB | AL19: 241405 | AM19: 84.65 | AN19: Pista Aeropuerto | AO19: Medio
A20: 50K6C | B20: Centro Sur | C20: Distrito Capital | D20: Bogotá | E20: GALERIAS | F20: 3 | G20: Alfonso Lopez | H20: ADMINISTRACIÓN Y ABASTECIMIENTO S.A.S. | I20: Esquinero | J20: 112.28 | K20: 1986 | L20: 1180 | M20: 49 | N20: 45747 | O20: 31 | P20: 1 | Q20: 31 | R20: 17 | S20: 6.2524725 | T20: -75.587859 | U20: =_xlfn.XLOOKUP(A20,'BD UM'!A:A,'BD UM'!B:B) -> 20223 | V20: =_xlfn.XLOOKUP(A20,'BD U6M'!A:A,'BD U6M'!B:B) -> 18255.167 | W20: =_xlfn.XLOOKUP(A20,'BD UM'!A:A,'BD UM'!C:C) -> 11271.8 | X20: =_xlfn.XLOOKUP(A20,'BD U6M'!A:A,'BD U6M'!C:C) -> 11584.4 | Y20: =_xlfn.XLOOKUP(A20,'BD UM'!A:A,'BD UM'!D:D) -> 227949.72 | Z20: =_xlfn.XLOOKUP(A20,'BD U6M'!A:A,'BD U6M'!D:D) -> 211475.91 | AA20: =_xlfn.XLOOKUP(A20,'BD UM'!A:A,'BD UM'!E:E) -> 13853.039 | AB20: =_xlfn.XLOOKUP(A20,'BD U6M'!A:A,'BD U6M'!E:E) -> 15408.897 | AC20: =_xlfn.XLOOKUP(A20,'BD UM'!A:A,'BD UM'!F:F) -> 67104.989 | AD20: =_xlfn.XLOOKUP(A20,'BD U6M'!A:A,'BD U6M'!F:F) -> 68591.339 | AE20: =_xlfn.XLOOKUP(A20,'BD UM'!A:A,'BD UM'!G:G) -> 10510 | AF20: =_xlfn.XLOOKUP(A20,'BD U6M'!A:A,'BD U6M'!G:G) -> 10611.425 | AG20: =_xlfn.XLOOKUP(A20,'BD UM'!A:A,'BD UM'!H:H) -> 1.4458 | AH20: COMERCIO/SERVICIO | AI20: ABIERTA | AJ20: BASE | AK20: EXP 2025 | AL20: 232000 | AM20: 93.61 | AN20: La Estrella 1 | AO20: Medio
A21: 50HZJ | B21: Occidente | C21: Antioquia | D21: Medellín | E21: LA CANDELARIA | F21: 4 | G21: Almacentro | H21: ALIANZA FIDUCIARIA - FIDEICOMISO ALMACENTRO INVERAL | I21: Esquinero | J21: 163.44 | K21: 0 | L21: 2459 | M21: 58 | N21: 45534 | O21: 30 | P21: 2 | Q21: 31 | R21: 24 | S21: 6.2357045 | T21: -75.570384 | U21: =_xlfn.XLOOKUP(A21,'BD UM'!A:A,'BD UM'!B:B) -> 23177 | V21: =_xlfn.XLOOKUP(A21,'BD U6M'!A:A,'BD U6M'!B:B) -> 21239.667 | W21: =_xlfn.XLOOKUP(A21,'BD UM'!A:A,'BD UM'!C:C) -> 9228.2 | X21: =_xlfn.XLOOKUP(A21,'BD U6M'!A:A,'BD U6M'!C:C) -> 9365 | Y21: =_xlfn.XLOOKUP(A21,'BD UM'!A:A,'BD UM'!D:D) -> 213880.96 | Z21: =_xlfn.XLOOKUP(A21,'BD U6M'!A:A,'BD U6M'!D:D) -> 198908.56 | AA21: =_xlfn.XLOOKUP(A21,'BD UM'!A:A,'BD UM'!E:E) -> 18269.134 | AB21: =_xlfn.XLOOKUP(A21,'BD U6M'!A:A,'BD U6M'!E:E) -> 14099.37 | AC21: =_xlfn.XLOOKUP(A21,'BD UM'!A:A,'BD UM'!F:F) -> 87293.543 | AD21: =_xlfn.XLOOKUP(A21,'BD U6M'!A:A,'BD U6M'!F:F) -> 79844.559 | AE21: =_xlfn.XLOOKUP(A21,'BD UM'!A:A,'BD UM'!G:G) -> 14212.166 | AF21: =_xlfn.XLOOKUP(A21,'BD U6M'!A:A,'BD U6M'!G:G) -> 14067.377 | AG21: =_xlfn.XLOOKUP(A21,'BD UM'!A:A,'BD UM'!H:H) -> 0 | AH21: COMERCIO/SERVICIO | AI21: ABIERTA | AJ21: RECESO | AK21: EXP 2024 | AL21: 204160 | AM21: 83.96 | AN21: Morato | AO21: Alto
A22: 50L8W | B22: Oriente | C22: Santander | D22: Bucaramanga | E22: ORIENTAL | F22: 3 | G22: Alonso Calle 19 | H22: 0 | I22: Esquinero | J22: 167.2 | K22: 2243 | L22: 76 | M22: 92 | N22: 45230 | O22: 31 | P22: 1 | Q22: 31 | R22: 34 | S22: 7.1312944 | T22: -73.115113 | U22: =_xlfn.XLOOKUP(A22,'BD UM'!A:A,'BD UM'!B:B) -> 18866 | V22: =_xlfn.XLOOKUP(A22,'BD U6M'!A:A,'BD U6M'!B:B) -> 17279 | W22: =_xlfn.XLOOKUP(A22,'BD UM'!A:A,'BD UM'!C:C) -> 10880.4 | X22: =_xlfn.XLOOKUP(A22,'BD U6M'!A:A,'BD U6M'!C:C) -> 11110.9 | Y22: =_xlfn.XLOOKUP(A22,'BD UM'!A:A,'BD UM'!D:D) -> 205268.89 | Z22: =_xlfn.XLOOKUP(A22,'BD U6M'!A:A,'BD U6M'!D:D) -> 191985.4 | AA22: =_xlfn.XLOOKUP(A22,'BD UM'!A:A,'BD UM'!E:E) -> 12984.094 | AB22: =_xlfn.XLOOKUP(A22,'BD U6M'!A:A,'BD U6M'!E:E) -> 13462.743 | AC22: =_xlfn.XLOOKUP(A22,'BD UM'!A:A,'BD UM'!F:F) -> 74786.325 | AD22: =_xlfn.XLOOKUP(A22,'BD U6M'!A:A,'BD U6M'!F:F) -> 69370.853 | AE22: =_xlfn.XLOOKUP(A22,'BD UM'!A:A,'BD UM'!G:G) -> 8047.379 | AF22: =_xlfn.XLOOKUP(A22,'BD U6M'!A:A,'BD U6M'!G:G) -> 8133.9457 | AG22: =_xlfn.XLOOKUP(A22,'BD UM'!A:A,'BD UM'!H:H) -> 0 | AH22: ALTA DENSIDAD | AI22: ABIERTA | AJ22: HOGAR | AK22: TMCB | AL22: 241405 | AM22: 48.13 | AN22: San Alonso | AO22: Medio
A23: 50SKG | B23: Centro Sur | C23: Distrito Capital | D23: Bogotá | E23: CASTILLA | F23: 3 | G23: Alsacia | H23: 0 | I23: Esquinero | J23: 119.06 | K23: 4224 | L23: 1630 | M23: 0 | N23: 44670 | O23: 19 | P23: 12 | Q23: 30 | R23: 52 | S23: 4.6481631 | T23: -74.134948 | U23: =_xlfn.XLOOKUP(A23,'BD UM'!A:A,'BD UM'!B:B) -> 21634 | V23: =_xlfn.XLOOKUP(A23,'BD U6M'!A:A,'BD U6M'!B:B) -> 21456.167 | W23: =_xlfn.XLOOKUP(A23,'BD UM'!A:A,'BD UM'!C:C) -> 15356.6 | X23: =_xlfn.XLOOKUP(A23,'BD U6M'!A:A,'BD U6M'!C:C) -> 15349.4 | Y23: =_xlfn.XLOOKUP(A23,'BD UM'!A:A,'BD UM'!D:D) -> 332225.11 | Z23: =_xlfn.XLOOKUP(A23,'BD U6M'!A:A,'BD U6M'!D:D) -> 329338.75 | AA23: =_xlfn.XLOOKUP(A23,'BD UM'!A:A,'BD UM'!E:E) -> 41656.004 | AB23: =_xlfn.XLOOKUP(A23,'BD U6M'!A:A,'BD U6M'!E:E) -> 40855.583 | AC23: =_xlfn.XLOOKUP(A23,'BD UM'!A:A,'BD UM'!F:F) -> 114004.32 | AD23: =_xlfn.XLOOKUP(A23,'BD U6M'!A:A,'BD U6M'!F:F) -> 109896.26 | AE23: =_xlfn.XLOOKUP(A23,'BD UM'!A:A,'BD UM'!G:G) -> 10250.848 | AF23: =_xlfn.XLOOKUP(A23,'BD U6M'!A:A,'BD U6M'!G:G) -> 10355.891 | AG23: =_xlfn.XLOOKUP(A23,'BD UM'!A:A,'BD UM'!H:H) -> 0 | AH23: ALTA DENSIDAD | AI23: ABIERTA | AJ23: HOGAR | AK23: TMCB | AL23: 241405 | AM23: 86.1 | AN23: Bonavista | AO23: Medio
A24: 50P88 | B24: Occidente | C24: Caldas | D24: Manizales | E24: ECOTURISTICO CERRO DE ORO | F24: 4 | G24: Alta Suiza | H24: LUZ CLEMENCIA SALAZAR RAMÍREZ, | I24: Medianero | J24: 125.27 | K24: 1922 | L24: 781 | M24: 56 | N24: 45590 | O24: 25 | P24: 7 | Q24: 31 | R24: 22 | S24: 5.0493157 | T24: -75.479528 | U24: =_xlfn.XLOOKUP(A24,'BD UM'!A:A,'BD UM'!B:B) -> 16621 | V24: =_xlfn.XLOOKUP(A24,'BD U6M'!A:A,'BD U6M'!B:B) -> 15438.167 | W24: =_xlfn.XLOOKUP(A24,'BD UM'!A:A,'BD UM'!C:C) -> 14834.6 | X24: =_xlfn.XLOOKUP(A24,'BD U6M'!A:A,'BD U6M'!C:C) -> 14403.6 | Y24: =_xlfn.XLOOKUP(A24,'BD UM'!A:A,'BD UM'!D:D) -> 246565.76 | Z24: =_xlfn.XLOOKUP(A24,'BD U6M'!A:A,'BD U6M'!D:D) -> 222364.98 | AA24: =_xlfn.XLOOKUP(A24,'BD UM'!A:A,'BD UM'!E:E) -> 22953.75 | AB24: =_xlfn.XLOOKUP(A24,'BD U6M'!A:A,'BD U6M'!E:E) -> 28595.254 | AC24: =_xlfn.XLOOKUP(A24,'BD UM'!A:A,'BD UM'!F:F) -> 94562.339 | AD24: =_xlfn.XLOOKUP(A24,'BD U6M'!A:A,'BD U6M'!F:F) -> 88667.603 | AE24: =_xlfn.XLOOKUP(A24,'BD UM'!A:A,'BD UM'!G:G) -> 7695 | AF24: =_xlfn.XLOOKUP(A24,'BD U6M'!A:A,'BD U6M'!G:G) -> 7942.7471 | AG24: =_xlfn.XLOOKUP(A24,'BD UM'!A:A,'BD UM'!H:H) -> 0 | AH24: COMERCIO/SERVICIO | AI24: ABIERTA | AJ24: BASE | AK24: EXP 2024 | AL24: 232000 | AM24: 62.98 | AN24: Junin | AO24: Medio
A25: 50PT8 | B25: Occidente | C25: Quindío | D25: Armenia | E25: EL CAFETERO | F25: 3 | G25: Altavista | H25: 0 | I25: Esquinero | J25: 97.07 | K25: 587 | L25: 3650 | M25: 56 | N25: 45377 | O25: 26 | P25: 6 | Q25: 31 | R25: 29 | S25: 4.5326893 | T25: -75.672029 | U25: =_xlfn.XLOOKUP(A25,'BD UM'!A:A,'BD UM'!B:B) -> 18888 | V25: =_xlfn.XLOOKUP(A25,'BD U6M'!A:A,'BD U6M'!B:B) -> 19783.833 | W25: =_xlfn.XLOOKUP(A25,'BD UM'!A:A,'BD UM'!C:C) -> 10080.9 | X25: =_xlfn.XLOOKUP(A25,'BD U6M'!A:A,'BD U6M'!C:C) -> 10417.2 | Y25: =_xlfn.XLOOKUP(A25,'BD UM'!A:A,'BD UM'!D:D) -> 190407.33 | Z25: =_xlfn.XLOOKUP(A25,'BD U6M'!A:A,'BD U6M'!D:D) -> 206092.97 | AA25: =_xlfn.XLOOKUP(A25,'BD UM'!A:A,'BD UM'!E:E) -> -6007.63 | AB25: =_xlfn.XLOOKUP(A25,'BD U6M'!A:A,'BD U6M'!E:E) -> 14772.491 | AC25: =_xlfn.XLOOKUP(A25,'BD UM'!A:A,'BD UM'!F:F) -> 74975.913 | AD25: =_xlfn.XLOOKUP(A25,'BD U6M'!A:A,'BD U6M'!F:F) -> 80156.934 | AE25: =_xlfn.XLOOKUP(A25,'BD UM'!A:A,'BD UM'!G:G) -> 9950.868 | AF25: =_xlfn.XLOOKUP(A25,'BD U6M'!A:A,'BD U6M'!G:G) -> 10052.634 | AG25: =_xlfn.XLOOKUP(A25,'BD UM'!A:A,'BD UM'!H:H) -> 0 | AH25: ADMINISTRATIVO | AI25: ABIERTA | AJ25: RECESO | AK25: TMCB | AL25: 204160 | AM25: 102.51 | AN25: Esmeralda | AO25: Alto
A26: 50L9T | B26: Norte | C26: Atlántico | D26: Barranquilla | E26: CENTRO HISTORICO | F26: 4 | G26: Alto Prado 76 | H26: H.U.B. SOLUCIONES INMOBILIARIAS S.A.S. | I26: Esquinero | J26: 145.99 | K26: 1086 | L26: 1055 | M26: 38 | N26: 45590 | O26: 25 | P26: 7 | Q26: 31 | R26: 22 | S26: 11.000576 | T26: -74.808289 | U26: =_xlfn.XLOOKUP(A26,'BD UM'!A:A,'BD UM'!B:B) -> 17728 | V26: =_xlfn.XLOOKUP(A26,'BD U6M'!A:A,'BD U6M'!B:B) -> 16446.833 | W26: =_xlfn.XLOOKUP(A26,'BD UM'!A:A,'BD UM'!C:C) -> 11408.5 | X26: =_xlfn.XLOOKUP(A26,'BD U6M'!A:A,'BD U6M'!C:C) -> 11312.4 | Y26: =_xlfn.XLOOKUP(A26,'BD UM'!A:A,'BD UM'!D:D) -> 202249.98 | Z26: =_xlfn.XLOOKUP(A26,'BD U6M'!A:A,'BD U6M'!D:D) -> 186053.13 | AA26: =_xlfn.XLOOKUP(A26,'BD UM'!A:A,'BD UM'!E:E) -> 10506.59 | AB26: =_xlfn.XLOOKUP(A26,'BD U6M'!A:A,'BD U6M'!E:E) -> 8558.2409 | AC26: =_xlfn.XLOOKUP(A26,'BD UM'!A:A,'BD UM'!F:F) -> 76424.28 | AD26: =_xlfn.XLOOKUP(A26,'BD U6M'!A:A,'BD U6M'!F:F) -> 69786.005 | AE26: =_xlfn.XLOOKUP(A26,'BD UM'!A:A,'BD UM'!G:G) -> 9468 | AF26: =_xlfn.XLOOKUP(A26,'BD U6M'!A:A,'BD U6M'!G:G) -> 9566.4788 | AG26: =_xlfn.XLOOKUP(A26,'BD UM'!A:A,'BD UM'!H:H) -> 0 | AH26: ADMINISTRATIVO | AI26: ABIERTA | AJ26: BASE | AK26: EXP 2024 | AL26: 232000 | AM26: 64.85 | AN26: 140 | AO26: Medio
A27: 50YHD | B27: Oriente | C27: Santander | D27: Bucaramanga | E27: CABECERA DEL LLANO | F27: 5 | G27: Altos De Cabecera 2 | H27: 0 | I27: Esquinero | J27: 78.85 | K27: 1464 | L27: 2130 | M27: 187 | N27: 45350 | O27: 28 | P27: 2 | Q27: 29 | R27: 30 | S27: 7.1212495 | T27: -73.110151 | U27: =_xlfn.XLOOKUP(A27,'BD UM'!A:A,'BD UM'!B:B) -> 22770 | V27: =_xlfn.XLOOKUP(A27,'BD U6M'!A:A,'BD U6M'!B:B) -> 21353.667 | W27: =_xlfn.XLOOKUP(A27,'BD UM'!A:A,'BD UM'!C:C) -> 10130.1 | X27: =_xlfn.XLOOKUP(A27,'BD U6M'!A:A,'BD U6M'!C:C) -> 10423.5 | Y27: =_xlfn.XLOOKUP(A27,'BD UM'!A:A,'BD UM'!D:D) -> 230662.79 | Z27: =_xlfn.XLOOKUP(A27,'BD U6M'!A:A,'BD U6M'!D:D) -> 222580.43 | AA27: =_xlfn.XLOOKUP(A27,'BD UM'!A:A,'BD UM'!E:E) -> 21651.656 | AB27: =_xlfn.XLOOKUP(A27,'BD U6M'!A:A,'BD U6M'!E:E) -> 22875.005 | AC27: =_xlfn.XLOOKUP(A27,'BD UM'!A:A,'BD UM'!F:F) -> 90718.378 | AD27: =_xlfn.XLOOKUP(A27,'BD U6M'!A:A,'BD U6M'!F:F) -> 86946.48 | AE27: =_xlfn.XLOOKUP(A27,'BD UM'!A:A,'BD UM'!G:G) -> 10504 | AF27: =_xlfn.XLOOKUP(A27,'BD U6M'!A:A,'BD U6M'!G:G) -> 10611.166 | AG27: =_xlfn.XLOOKUP(A27,'BD UM'!A:A,'BD UM'!H:H) -> 0 | AH27: ADMINISTRATIVO | AI27: ABIERTA | AJ27: BASE | AK27: TMCB | AL27: 232000 | AM27: 133.21 | AN27: Sotomayor | AO27: Alto
A28: 50Y4E | B28: Centro Sur | C28: Cundinamarca | D28: Madrid | E28: MADRID | F28: 3 | G28: Altos Del Ciclista | H28: RICARDO JUNCA GARZON | I28: Esquinero | J28: 127.82 | K28: 134 | L28: 1253 | M28: 115 | N28: 45510 | O28: 6 | P28: 26 | Q28: 31 | R28: 24 | S28: 4.8154064 | T28: -74.222889 | U28: =_xlfn.XLOOKUP(A28,'BD UM'!A:A,'BD UM'!B:B) -> 11410 | V28: =_xlfn.XLOOKUP(A28,'BD U6M'!A:A,'BD U6M'!B:B) -> 11328.5 | W28: =_xlfn.XLOOKUP(A28,'BD UM'!A:A,'BD UM'!C:C) -> 15005.4 | X28: =_xlfn.XLOOKUP(A28,'BD U6M'!A:A,'BD U6M'!C:C) -> 15380.3 | Y28: =_xlfn.XLOOKUP(A28,'BD UM'!A:A,'BD UM'!D:D) -> 171211.57 | Z28: =_xlfn.XLOOKUP(A28,'BD U6M'!A:A,'BD U6M'!D:D) -> 174235.29 | AA28: =_xlfn.XLOOKUP(A28,'BD UM'!A:A,'BD UM'!E:E) -> 11439.399 | AB28: =_xlfn.XLOOKUP(A28,'BD U6M'!A:A,'BD U6M'!E:E) -> 7479.0417 | AC28: =_xlfn.XLOOKUP(A28,'BD UM'!A:A,'BD UM'!F:F) -> 65210.841 | AD28: =_xlfn.XLOOKUP(A28,'BD U6M'!A:A,'BD U6M'!F:F) -> 64739.497 | AE28: =_xlfn.XLOOKUP(A28,'BD UM'!A:A,'BD UM'!G:G) -> 6831.5 | AF28: =_xlfn.XLOOKUP(A28,'BD U6M'!A:A,'BD U6M'!G:G) -> 6723.0514 | AG28: =_xlfn.XLOOKUP(A28,'BD UM'!A:A,'BD UM'!H:H) -> 0 | AH28: TRANSPORTE | AI28: ABIERTA | AJ28: RECESO | AK28: EXP 2024 | AL28: 204160 | AM28: 52.67 | AN28: Giron El Poblado | AO28: Medio
A29: 501YH | B29: Centro Sur | C29: Distrito Capital | D29: Bogotá | E29: AMERICAS | F29: 3 | G29: America Occidental | H29: CALZADO DE LA SABANA S.A.S. | I29: Medianero | J29: 116.55 | K29: 622 | L29: 2103 | M29: 0 | N29: 43535 | O29: 11 | P29: 21 | Q29: 31 | R29: 89 | S29: 4.6185998 | T29: -74.1385 | U29: =_xlfn.XLOOKUP(A29,'BD UM'!A:A,'BD UM'!B:B) -> 18695 | V29: =_xlfn.XLOOKUP(A29,'BD U6M'!A:A,'BD U6M'!B:B) -> 18560 | W29: =_xlfn.XLOOKUP(A29,'BD UM'!A:A,'BD UM'!C:C) -> 11297.3 | X29: =_xlfn.XLOOKUP(A29,'BD U6M'!A:A,'BD U6M'!C:C) -> 11156.7 | Y29: =_xlfn.XLOOKUP(A29,'BD UM'!A:A,'BD UM'!D:D) -> 211202.33 | Z29: =_xlfn.XLOOKUP(A29,'BD U6M'!A:A,'BD U6M'!D:D) -> 207067.64 | AA29: =_xlfn.XLOOKUP(A29,'BD UM'!A:A,'BD UM'!E:E) -> 9623.01 | AB29: =_xlfn.XLOOKUP(A29,'BD U6M'!A:A,'BD U6M'!E:E) -> 9837.3472 | AC29: =_xlfn.XLOOKUP(A29,'BD UM'!A:A,'BD UM'!F:F) -> 69830.896 | AD29: =_xlfn.XLOOKUP(A29,'BD U6M'!A:A,'BD U6M'!F:F) -> 67793.063 | AE29: =_xlfn.XLOOKUP(A29,'BD UM'!A:A,'BD UM'!G:G) -> 12270.539 | AF29: =_xlfn.XLOOKUP(A29,'BD U6M'!A:A,'BD U6M'!G:G) -> 12392.518 | AG29: =_xlfn.XLOOKUP(A29,'BD UM'!A:A,'BD UM'!H:H) -> 0 | AH29: COMERCIO/SERVICIO | AI29: ABIERTA | AJ29: BASE | AK29: TMCB | AL29: 232000 | AM29: 105.29 | AN29: Chapinero | AO29: Medio
A30: 50LTJ | B30: Centro Sur | C30: Distrito Capital | D30: Bogotá | E30: PUENTE ARANDA | F30: 3 | G30: Américas | H30: SI SISTEMA INTEGRAL INMOBILIARIO S.A.S. | I30: Medianero | J30: 122.76 | K30: 0 | L30: 5900 | M30: 77 | N30: 45899 | O30: 30 | P30: 2 | Q30: 31 | R30: 12 | S30: 4.6299456 | T30: -74.110935 | U30: =_xlfn.XLOOKUP(A30,'BD UM'!A:A,'BD UM'!B:B) -> 19234 | V30: =_xlfn.XLOOKUP(A30,'BD U6M'!A:A,'BD U6M'!B:B) -> 19762.833 | W30: =_xlfn.XLOOKUP(A30,'BD UM'!A:A,'BD UM'!C:C) -> 10064.9 | X30: =_xlfn.XLOOKUP(A30,'BD U6M'!A:A,'BD U6M'!C:C) -> 10409 | Y30: =_xlfn.XLOOKUP(A30,'BD UM'!A:A,'BD UM'!D:D) -> 193588.4 | Z30: =_xlfn.XLOOKUP(A30,'BD U6M'!A:A,'BD U6M'!D:D) -> 205712.05 | AA30: =_xlfn.XLOOKUP(A30,'BD UM'!A:A,'BD UM'!E:E) -> 19846.903 | AB30: =_xlfn.XLOOKUP(A30,'BD U6M'!A:A,'BD U6M'!E:E) -> 22823.348 | AC30: =_xlfn.XLOOKUP(A30,'BD UM'!A:A,'BD UM'!F:F) -> 82103.287 | AD30: =_xlfn.XLOOKUP(A30,'BD U6M'!A:A,'BD U6M'!F:F) -> 83978.55 | AE30: =_xlfn.XLOOKUP(A30,'BD UM'!A:A,'BD UM'!G:G) -> 13052.1 | AF30: =_xlfn.XLOOKUP(A30,'BD U6M'!A:A,'BD U6M'!G:G) -> 12772.744 | AG30: =_xlfn.XLOOKUP(A30,'BD UM'!A:A,'BD UM'!H:H) -> 1.698 | AH30: COMERCIO/SERVICIO | AI30: ABIERTA | AJ30: BASE | AK30: EXP 2024 | AL30: 232000 | AM30: 62.65 | AN30: Primera 27 | AO30: Medio
A31: 50417 | B31: Centro Sur | C31: Distrito Capital | D31: Bogotá | E31: AMERICAS | F31: 3 | G31: Américas 72 | H31: CLAUDIO ENRIQUE BRICEÑO BERMUDEZ | I31: Esquinero | J31: 167.49 | K31: 1717 | L31: 983 | M31: 315 | N31: 45595 | O31: 30 | P31: 2 | Q31: 31 | R31: 22 | S31: 4.6256917 | T31: -74.138007 | U31: =_xlfn.XLOOKUP(A31,'BD UM'!A:A,'BD UM'!B:B) -> 14069 | V31: =_xlfn.XLOOKUP(A31,'BD U6M'!A:A,'BD U6M'!B:B) -> 14060.833 | W31: =_xlfn.XLOOKUP(A31,'BD UM'!A:A,'BD UM'!C:C) -> 12737.5 | X31: =_xlfn.XLOOKUP(A31,'BD U6M'!A:A,'BD U6M'!C:C) -> 12606.2 | Y31: =_xlfn.XLOOKUP(A31,'BD UM'!A:A,'BD UM'!D:D) -> 179203.72 | Z31: =_xlfn.XLOOKUP(A31,'BD U6M'!A:A,'BD U6M'!D:D) -> 177254.33 | AA31: =_xlfn.XLOOKUP(A31,'BD UM'!A:A,'BD UM'!E:E) -> 7304.356 | AB31: =_xlfn.XLOOKUP(A31,'BD U6M'!A:A,'BD U6M'!E:E) -> 6272.3101 | AC31: =_xlfn.XLOOKUP(A31,'BD UM'!A:A,'BD UM'!F:F) -> 63036.422 | AD31: =_xlfn.XLOOKUP(A31,'BD U6M'!A:A,'BD U6M'!F:F) -> 61775.952 | AE31: =_xlfn.XLOOKUP(A31,'BD UM'!A:A,'BD UM'!G:G) -> 10494 | AF31: =_xlfn.XLOOKUP(A31,'BD U6M'!A:A,'BD U6M'!G:G) -> 10601.082 | AG31: =_xlfn.XLOOKUP(A31,'BD UM'!A:A,'BD UM'!H:H) -> 0 | AH31: COMERCIO/SERVICIO | AI31: ABIERTA | AJ31: RECESO | AK31: EXP 2025 | AL31: 204160 | AM31: 95.4 | AN31: America Occidental | AO31: Medio
A32: 50VOZ | B32: Centro Sur | C32: Distrito Capital | D32: Bogotá | E32: AMERICAS | F32: 3 | G32: Américas Boyacá | H32: JOHN EDISON GIRALDO GIRALDO, ELKIN URIEL ARISTIZABAL BOTERO, GILBERTO ANDRES OCHOA CEBALLOS, LUIS ALEJANDRO OCHOA CEBALLOS, CESAR AUGUSTO OCHOA OSPINA Y ASTRID JOHANNA MESA HERRERA. | I32: Medianero | J32: 142.56 | K32: 430 | L32: 1177 | M32: 190 | N32: 45866 | O32: 28 | P32: 4 | Q32: 31 | R32: 13 | S32: 4.6166961 | T32: -74.137253 | U32: =_xlfn.XLOOKUP(A32,'BD UM'!A:A,'BD UM'!B:B) -> 18308 | V32: =_xlfn.XLOOKUP(A32,'BD U6M'!A:A,'BD U6M'!B:B) -> 17832.667 | W32: =_xlfn.XLOOKUP(A32,'BD UM'!A:A,'BD UM'!C:C) -> 12084.4 | X32: =_xlfn.XLOOKUP(A32,'BD U6M'!A:A,'BD U6M'!C:C) -> 11919.8 | Y32: =_xlfn.XLOOKUP(A32,'BD UM'!A:A,'BD UM'!D:D) -> 221241.11 | Z32: =_xlfn.XLOOKUP(A32,'BD U6M'!A:A,'BD U6M'!D:D) -> 212561.54 | AA32: =_xlfn.XLOOKUP(A32,'BD UM'!A:A,'BD UM'!E:E) -> 13604.747 | AB32: =_xlfn.XLOOKUP(A32,'BD U6M'!A:A,'BD U6M'!E:E) -> 10391.25 | AC32: =_xlfn.XLOOKUP(A32,'BD UM'!A:A,'BD UM'!F:F) -> 72420.387 | AD32: =_xlfn.XLOOKUP(A32,'BD U6M'!A:A,'BD U6M'!F:F) -> 70428.873 | AE32: =_xlfn.XLOOKUP(A32,'BD UM'!A:A,'BD UM'!G:G) -> 14275 | AF32: =_xlfn.XLOOKUP(A32,'BD U6M'!A:A,'BD U6M'!G:G) -> 13948.538 | AG32: =_xlfn.XLOOKUP(A32,'BD UM'!A:A,'BD UM'!H:H) -> 1.4992 | AH32: ESTACION DE SERVICIO | AI32: ABIERTA | AJ32: RECESO | AK32: TMCB | AL32: 204160 | AM32: 70.38 | AN32: Eds Molino | AO32: Medio
A33: 50IP7 | B33: Oriente | C33: Santander | D33: Floridablanca | E33: FLORIDABLANCA | F33: 4 | G33: Anillo Vial | H33: 0 | I33: Medianero | J33: 120.52 | K33: 30 | L33: 170 | M33: 52 | N33: 45016 | O33: 31 | P33: 1 | Q33: 31 | R33: 41 | S33: 7.0632186 | T33: -73.146089 | U33: =_xlfn.XLOOKUP(A33,'BD UM'!A:A,'BD UM'!B:B) -> 16419 | V33: =_xlfn.XLOOKUP(A33,'BD U6M'!A:A,'BD U6M'!B:B) -> 15852.167 | W33: =_xlfn.XLOOKUP(A33,'BD UM'!A:A,'BD UM'!C:C) -> 12780 | X33: =_xlfn.XLOOKUP(A33,'BD U6M'!A:A,'BD U6M'!C:C) -> 13725.4 | Y33: =_xlfn.XLOOKUP(A33,'BD UM'!A:A,'BD UM'!D:D) -> 209835.22 | Z33: =_xlfn.XLOOKUP(A33,'BD U6M'!A:A,'BD U6M'!D:D) -> 217577.3 | AA33: =_xlfn.XLOOKUP(A33,'BD UM'!A:A,'BD UM'!E:E) -> 15604.528 | AB33: =_xlfn.XLOOKUP(A33,'BD U6M'!A:A,'BD U6M'!E:E) -> 22111.743 | AC33: =_xlfn.XLOOKUP(A33,'BD UM'!A:A,'BD UM'!F:F) -> 82956.152 | AD33: =_xlfn.XLOOKUP(A33,'BD U6M'!A:A,'BD U6M'!F:F) -> 81957.446 | AE33: =_xlfn.XLOOKUP(A33,'BD UM'!A:A,'BD UM'!G:G) -> 8481.949 | AF33: =_xlfn.XLOOKUP(A33,'BD U6M'!A:A,'BD U6M'!G:G) -> 8583.6107 | AG33: =_xlfn.XLOOKUP(A33,'BD UM'!A:A,'BD UM'!H:H) -> 0 | AH33: ALTA DENSIDAD | AI33: ABIERTA | AJ33: HOGAR | AK33: TMCB | AL33: 241405 | AM33: 79.4 | AN33: Cedro | AO33: Medio
A34: 502XT | B34: Centro Norte | C34: Distrito Capital | D34: Bogotá | E34: LOS CEDROS | F34: 5 | G34: Antigua | H34: 0 | I34: Esquinero | J34: 139.26 | K34: 2248 | L34: 263 | M34: 28 | N34: 45412 | O34: 30 | P34: 1 | Q34: 30 | R34: 28 | S34: 4.7143477 | T34: -74.03684 | U34: =_xlfn.XLOOKUP(A34,'BD UM'!A:A,'BD UM'!B:B) -> 15328 | V34: =_xlfn.XLOOKUP(A34,'BD U6M'!A:A,'BD U6M'!B:B) -> 14805.167 | W34: =_xlfn.XLOOKUP(A34,'BD UM'!A:A,'BD UM'!C:C) -> 14328.3 | X34: =_xlfn.XLOOKUP(A34,'BD U6M'!A:A,'BD U6M'!C:C) -> 14475.7 | Y34: =_xlfn.XLOOKUP(A34,'BD UM'!A:A,'BD UM'!D:D) -> 219624.63 | Z34: =_xlfn.XLOOKUP(A34,'BD U6M'!A:A,'BD U6M'!D:D) -> 214314.87 | AA34: =_xlfn.XLOOKUP(A34,'BD UM'!A:A,'BD UM'!E:E) -> 16556.697 | AB34: =_xlfn.XLOOKUP(A34,'BD U6M'!A:A,'BD U6M'!E:E) -> 15444.616 | AC34: =_xlfn.XLOOKUP(A34,'BD UM'!A:A,'BD UM'!F:F) -> 79846.129 | AD34: =_xlfn.XLOOKUP(A34,'BD U6M'!A:A,'BD U6M'!F:F) -> 77595.142 | AE34: =_xlfn.XLOOKUP(A34,'BD UM'!A:A,'BD UM'!G:G) -> 11056.52 | AF34: =_xlfn.XLOOKUP(A34,'BD U6M'!A:A,'BD U6M'!G:G) -> 11073.916 | AG34: =_xlfn.XLOOKUP(A34,'BD UM'!A:A,'BD UM'!H:H) -> 0 | AH34: ALTA DENSIDAD | AI34: ABIERTA | AJ34: HOGAR | AK34: EXP 2024 | AL34: 241405 | AM34: 77.38 | AN34: Foresta Norte Armeni | AO34: Medio
A35: 50OMJ | B35: Occidente | C35: Quindío | D35: Armenia | E35: QUIMBAYA | F35: 5 | G35: Aquazul | H35: INVERSIONES CABO VERDE S.A.S | I35: Esquinero | J35: 115.56 | K35: 3162 | L35: 0 | M35: 55 | N35: 45647 | O35: 21 | P35: 11 | Q35: 31 | R35: 20 | S35: 4.5616803 | T35: -75.657848 | U35: =_xlfn.XLOOKUP(A35,'BD UM'!A:A,'BD UM'!B:B) -> 12999 | V35: =_xlfn.XLOOKUP(A35,'BD U6M'!A:A,'BD U6M'!B:B) -> 12680 | W35: =_xlfn.XLOOKUP(A35,'BD UM'!A:A,'BD UM'!C:C) -> 13326 | X35: =_xlfn.XLOOKUP(A35,'BD U6M'!A:A,'BD U6M'!C:C) -> 13367.5 | Y35: =_xlfn.XLOOKUP(A35,'BD UM'!A:A,'BD UM'!D:D) -> 173224.77 | Z35: =_xlfn.XLOOKUP(A35,'BD U6M'!A:A,'BD U6M'!D:D) -> 169500.42 | AA35: =_xlfn.XLOOKUP(A35,'BD UM'!A:A,'BD UM'!E:E) -> -3080.598 | AB35: =_xlfn.XLOOKUP(A35,'BD U6M'!A:A,'BD U6M'!E:E) -> 6868.7623 | AC35: =_xlfn.XLOOKUP(A35,'BD UM'!A:A,'BD UM'!F:F) -> 65921.256 | AD35: =_xlfn.XLOOKUP(A35,'BD U6M'!A:A,'BD U6M'!F:F) -> 62170.732 | AE35: =_xlfn.XLOOKUP(A35,'BD UM'!A:A,'BD UM'!G:G) -> 8942 | AF35: =_xlfn.XLOOKUP(A35,'BD U6M'!A:A,'BD U6M'!G:G) -> 9036.0682 | AG35: =_xlfn.XLOOKUP(A35,'BD UM'!A:A,'BD UM'!H:H) -> 0 | AH35: COMERCIO/SERVICIO | AI35: ABIERTA | AJ35: BASE | AK35: TMCB | AL35: 232000 | AM35: 123.28 | AN35: Pista Aeropuerto | AO35: Alto
A36: 50CV4 | B36: Occidente | C36: Valle del Cauca | D36: Cali | E36: CALI | F36: 4 | G36: Arbolatta Mall | H36: 0 | I36: Esquinero | J36: 98.65 | K36: 2200 | L36: 320 | M36: 63 | N36: 45435 | O36: 23 | P36: 9 | Q36: 31 | R36: 27 | S36: 3.3603253 | T36: -76.515519 | U36: =_xlfn.XLOOKUP(A36,'BD UM'!A:A,'BD UM'!B:B) -> 19624 | V36: =_xlfn.XLOOKUP(A36,'BD U6M'!A:A,'BD U6M'!B:B) -> 17401.5 | W36: =_xlfn.XLOOKUP(A36,'BD UM'!A:A,'BD UM'!C:C) -> 14526.1 | X36: =_xlfn.XLOOKUP(A36,'BD U6M'!A:A,'BD U6M'!C:C) -> 14281.2 | Y36: =_xlfn.XLOOKUP(A36,'BD UM'!A:A,'BD UM'!D:D) -> 285060.19 | Z36: =_xlfn.XLOOKUP(A36,'BD U6M'!A:A,'BD U6M'!D:D) -> 248513.68 | AA36: =_xlfn.XLOOKUP(A36,'BD UM'!A:A,'BD UM'!E:E) -> 31153.137 | AB36: =_xlfn.XLOOKUP(A36,'BD U6M'!A:A,'BD U6M'!E:E) -> 25320.448 | AC36: =_xlfn.XLOOKUP(A36,'BD UM'!A:A,'BD UM'!F:F) -> 110128.91 | AD36: =_xlfn.XLOOKUP(A36,'BD U6M'!A:A,'BD U6M'!F:F) -> 94196.101 | AE36: =_xlfn.XLOOKUP(A36,'BD UM'!A:A,'BD UM'!G:G) -> 12162.172 | AF36: =_xlfn.XLOOKUP(A36,'BD U6M'!A:A,'BD U6M'!G:G) -> 12122.962 | AG36: =_xlfn.XLOOKUP(A36,'BD UM'!A:A,'BD UM'!H:H) -> 0 | AH36: ALTA DENSIDAD | AI36: ABIERTA | AJ36: HOGAR | AK36: TMCB | AL36: 241405 | AM36: 60.57 | AN36: Santa Matilde | AO36: Medio
A37: 50R0P | B37: Centro Sur | C37: Distrito Capital | D37: Bogotá | E37: SANTA CECILIA | F37: 3 | G37: Arrayanes | H37: 0 | I37: Esquinero | J37: 106.29 | K37: 2615 | L37: 335 | M37: 155 | N37: 45169 | O37: 31 | P37: 1 | Q37: 31 | R37: 36 | S37: 4.6807622 | T37: -74.113838 | U37: =_xlfn.XLOOKUP(A37,'BD UM'!A:A,'BD UM'!B:B) -> 14520 | V37: =_xlfn.XLOOKUP(A37,'BD U6M'!A:A,'BD U6M'!B:B) -> 14616.167 | W37: =_xlfn.XLOOKUP(A37,'BD UM'!A:A,'BD UM'!C:C) -> 13143.6 | X37: =_xlfn.XLOOKUP(A37,'BD U6M'!A:A,'BD U6M'!C:C) -> 12953.7 | Y37: =_xlfn.XLOOKUP(A37,'BD UM'!A:A,'BD UM'!D:D) -> 190845.29 | Z37: =_xlfn.XLOOKUP(A37,'BD U6M'!A:A,'BD U6M'!D:D) -> 189332.89 | AA37: =_xlfn.XLOOKUP(A37,'BD UM'!A:A,'BD UM'!E:E) -> 11576.281 | AB37: =_xlfn.XLOOKUP(A37,'BD U6M'!A:A,'BD U6M'!E:E) -> 9741.9539 | AC37: =_xlfn.XLOOKUP(A37,'BD UM'!A:A,'BD UM'!F:F) -> 62654.675 | AD37: =_xlfn.XLOOKUP(A37,'BD U6M'!A:A,'BD U6M'!F:F) -> 61034.232 | AE37: =_xlfn.XLOOKUP(A37,'BD UM'!A:A,'BD UM'!G:G) -> 6766.236 | AF37: =_xlfn.XLOOKUP(A37,'BD U6M'!A:A,'BD U6M'!G:G) -> 6591.2473 | AG37: =_xlfn.XLOOKUP(A37,'BD UM'!A:A,'BD UM'!H:H) -> 0 | AH37: ADMINISTRATIVO | AI37: ABIERTA | AJ37: RECESO | AK37: EXP 2025 | AL37: 204160 | AM37: 47.41 | AN37: Dorado Plaza | AO37: Medio
A38: 50B6R | B38: Centro Sur | C38: Distrito Capital | D38: Bogotá | E38: CIUDAD SALITRE OCCIDENTAL | F38: 4 | G38: Arrecife | H38: MCJ INVERSIONES S.A.S. | I38: Esquinero | J38: 144.1 | K38: 395 | L38: 4660 | M38: 0 | N38: 45771 | O38: 24 | P38: 7 | Q38: 30 | R38: 16 | S38: 4.6482314 | T38: -74.101443 | U38: =_xlfn.XLOOKUP(A38,'BD UM'!A:A,'BD UM'!B:B) -> 13277 | V38: =_xlfn.XLOOKUP(A38,'BD U6M'!A:A,'BD U6M'!B:B) -> 13416.5 | W38: =_xlfn.XLOOKUP(A38,'BD UM'!A:A,'BD UM'!C:C) -> 8997.1 | X38: =_xlfn.XLOOKUP(A38,'BD U6M'!A:A,'BD U6M'!C:C) -> 9427.2 | Y38: =_xlfn.XLOOKUP(A38,'BD UM'!A:A,'BD UM'!D:D) -> 119453.92 | Z38: =_xlfn.XLOOKUP(A38,'BD U6M'!A:A,'BD U6M'!D:D) -> 126479.84 | AA38: =_xlfn.XLOOKUP(A38,'BD UM'!A:A,'BD UM'!E:E) -> 4111.511 | AB38: =_xlfn.XLOOKUP(A38,'BD U6M'!A:A,'BD U6M'!E:E) -> 7128.1676 | AC38: =_xlfn.XLOOKUP(A38,'BD UM'!A:A,'BD UM'!F:F) -> 51466.877 | AD38: =_xlfn.XLOOKUP(A38,'BD U6M'!A:A,'BD U6M'!F:F) -> 52590.503 | AE38: =_xlfn.XLOOKUP(A38,'BD UM'!A:A,'BD UM'!G:G) -> 6831.5 | AF38: =_xlfn.XLOOKUP(A38,'BD U6M'!A:A,'BD U6M'!G:G) -> 6862.1819 | AG38: =_xlfn.XLOOKUP(A38,'BD UM'!A:A,'BD UM'!H:H) -> 1.1944 | AH38: COMERCIO/SERVICIO | AI38: ABIERTA | AJ38: BASE | AK38: TMCB | AL38: 232000 | AM38: 58.13 | AN38: Chicamocha | AO38: Medio
A39: 50ZFN | B39: Oriente | C39: Santander | D39: Bucaramanga | E39: LA PEDREGOSA | F39: 3 | G39: Asturias | H39: 0 | I39: Esquinero | J39: 100.67 | K39: 770 | L39: 510 | M39: 46 | N39: 44890 | O39: 25 | P39: 6 | Q39: 30 | R39: 45 | S39: 7.0895364 | T39: -73.107467 | U39: =_xlfn.XLOOKUP(A39,'BD UM'!A:A,'BD UM'!B:B) -> 16512 | V39: =_xlfn.XLOOKUP(A39,'BD U6M'!A:A,'BD U6M'!B:B) -> 16162 | W39: =_xlfn.XLOOKUP(A39,'BD UM'!A:A,'BD UM'!C:C) -> 10595.3 | X39: =_xlfn.XLOOKUP(A39,'BD U6M'!A:A,'BD U6M'!C:C) -> 10791.3 | Y39: =_xlfn.XLOOKUP(A39,'BD UM'!A:A,'BD UM'!D:D) -> 174950.37 | Z39: =_xlfn.XLOOKUP(A39,'BD U6M'!A:A,'BD U6M'!D:D) -> 174408.44 | AA39: =_xlfn.XLOOKUP(A39,'BD UM'!A:A,'BD UM'!E:E) -> 4645.578 | AB39: =_xlfn.XLOOKUP(A39,'BD U6M'!A:A,'BD U6M'!E:E) -> 6598.9899 | AC39: =_xlfn.XLOOKUP(A39,'BD UM'!A:A,'BD UM'!F:F) -> 61332.33 | AD39: =_xlfn.XLOOKUP(A39,'BD U6M'!A:A,'BD U6M'!F:F) -> 60600.201 | AE39: =_xlfn.XLOOKUP(A39,'BD UM'!A:A,'BD UM'!G:G) -> 5852.054 | AF39: =_xlfn.XLOOKUP(A39,'BD U6M'!A:A,'BD U6M'!G:G) -> 5920.2128 | AG39: =_xlfn.XLOOKUP(A39,'BD UM'!A:A,'BD UM'!H:H) -> 0 | AH39: ADMINISTRATIVO | AI39: ABIERTA | AJ39: BASE | AK39: TMCB | AL39: 232000 | AM39: 128.9 | AN39: PT | AO39: Alto
A40: 504EU | B40: Centro Norte | C40: Distrito Capital | D40: Bogotá | E40: EL PRADO | F40: 4 | G40: Atabanza | H40: 0 | I40: Esquinero | J40: 150 | K40: 3207 | L40: 1461 | M40: 0 | N40: 43453 | O40: 19 | P40: 13 | Q40: 31 | R40: 92 | S40: 4.7094003 | T40: -74.0617 | U40: =_xlfn.XLOOKUP(A40,'BD UM'!A:A,'BD UM'!B:B) -> 31142 | V40: =_xlfn.XLOOKUP(A40,'BD U6M'!A:A,'BD U6M'!B:B) -> 32653.5 | W40: =_xlfn.XLOOKUP(A40,'BD UM'!A:A,'BD UM'!C:C) -> 12639.7 | X40: =_xlfn.XLOOKUP(A40,'BD U6M'!A:A,'BD U6M'!C:C) -> 12853.3 | Y40: =_xlfn.XLOOKUP(A40,'BD UM'!A:A,'BD UM'!D:D) -> 393626.4 | Z40: =_xlfn.XLOOKUP(A40,'BD U6M'!A:A,'BD U6M'!D:D) -> 419705.45 | AA40: =_xlfn.XLOOKUP(A40,'BD UM'!A:A,'BD UM'!E:E) -> 62055.343 | AB40: =_xlfn.XLOOKUP(A40,'BD U6M'!A:A,'BD U6M'!E:E) -> 64561.956 | AC40: =_xlfn.XLOOKUP(A40,'BD UM'!A:A,'BD UM'!F:F) -> 148038.29 | AD40: =_xlfn.XLOOKUP(A40,'BD U6M'!A:A,'BD U6M'!F:F) -> 156035.39 | AE40: =_xlfn.XLOOKUP(A40,'BD UM'!A:A,'BD UM'!G:G) -> 19334.793 | AF40: =_xlfn.XLOOKUP(A40,'BD U6M'!A:A,'BD U6M'!G:G) -> 19604.57 | AG40: =_xlfn.XLOOKUP(A40,'BD UM'!A:A,'BD UM'!H:H) -> 0 | AH40: EDUCACION | AI40: ABIERTA | AJ40: BASE | AK40: TMCB | AL40: 232000 | AM40: 65.47 | AN40: Gran Provenza | AO40: Alto
...

Sheet HISTORICO VENTAS
A2: Tienda 2026 | B2: (Varios elementos)
A3: Mes | B3: (Varios elementos)
A5: $ Ventas Operativas Prom. Tienda | B5: Etiquetas de columna
A6: Etiquetas de fila | B6: ene 17 | C6: feb 17 | D6: mar 17 | E6: abr 17 | F6: may 17 | G6: jun 17 | H6: jul 17 | I6: ago 17 | J6: sep 17 | K6: oct 17 | L6: nov 17 | M6: ene 18 | N6: feb 18 | O6: mar 18 | P6: abr 18 | Q6: may 18 | R6: jun 18 | S6: jul 18 | T6: ago 18 | U6: sep 18 | V6: oct 18 | W6: nov 18 | X6: ene 19 | Y6: feb 19 | Z6: mar 19 | AA6: abr 19 | AB6: may 19 | AC6: jun 19 | AD6: jul 19 | AE6: ago 19 | AF6: sep 19 | AG6: oct 19 | AH6: nov 19 | AI6: ene 20 | AJ6: feb 20 | AK6: mar 20 | AL6: abr 20 | AM6: may 20 | AN6: jun 20 | AO6: jul 20 | AP6: ago 20 | AQ6: sep 20 | AR6: oct 20 | AS6: nov 20 | AT6: ene 21 | AU6: feb 21 | AV6: mar 21 | AW6: abr 21 | AX6: may 21 | AY6: jun 21 | AZ6: jul 21 | BA6: ago 21 | BB6: sep 21 | BC6: oct 21 | BD6: nov 21 | BE6: ene 22 | BF6: feb 22 | BG6: mar 22 | BH6: abr 22 | BI6: may 22 | BJ6: jun 22 | BK6: jul 22 | BL6: ago 22 | BM6: sep 22 | BN6: oct 22 | BO6: nov 22 | BP6: ene 23 | BQ6: feb 23 | BR6: mar 23 | BS6: abr 23 | BT6: may 23 | BU6: jun 23 | BV6: jul 23 | BW6: ago 23 | BX6: sep 23 | BY6: oct 23 | BZ6: nov 23 | CA6: ene 24 | CB6: feb 24 | CC6: mar 24 | CD6: abr 24 | CE6: may 24 | CF6: jun 24 | CG6: jul 24 | CH6: ago 24 | CI6: sep 24 | CJ6: oct 24 | CK6: nov 24 | CL6: ene 25 | CM6: feb 25 | CN6: mar 25 | CO6: abr 25 | CP6: may 25 | CQ6: jun 25 | CR6: jul 25 | CS6: ago 25 | CT6: sep 25 | CU6: oct 25 | CV6: nov 25 | CW6: ene 26 | CX6: feb 26 | CY6: mar 26 | CZ6: abr 26 | DA6: may 26 | DB6: jun 26 | DC6: jul 26 | DD6: ago 26 | DE6: Total general
A7: 5002I | CK7: 7892.3915 | CL7: 133622.78 | CM7: 130162.6 | CN7: 165446.71 | CO7: 155130.55 | CP7: 168167.91 | CQ7: 180130.21 | CR7: 158749.31 | CS7: 168918.3 | CT7: 164454.68 | CU7: 190613.36 | CV7: 190541.74 | CW7: 172193.18 | CX7: 154072.74 | CY7: 197528.5 | CZ7: 195420.18 | DA7: 205164.95 | DB7: 198609.13 | DC7: 211442.47 | DD7: 211069.4 | DE7: 167966.55
A8: 5003A | BB8: 50668.778 | BC8: 140328.39 | BD8: 133315.78 | BE8: 190114.56 | BF8: 168804.24 | BG8: 177242.48 | BH8: 198958.6 | BI8: 207040.82 | BJ8: 197291.25 | BK8: 225744.63 | BL8: 198939.39 | BM8: 195737.7 | BN8: 216992.6 | BO8: 199838.52 | BP8: 203381.58 | BQ8: 189512.27 | BR8: 200283.46 | BS8: 217666.11 | BT8: 200524.65 | BU8: 202229.44 | BV8: 201901.59 | BW8: 191294.39 | BX8: 190140.85 | BY8: 183013.32 | BZ8: 182385.76 | CA8: 209076.3 | CB8: 185759.85 | CC8: 211464.33 | CD8: 182464.31 | CE8: 197493.88 | CF8: 207410.27 | CG8: 208027.5 | CH8: 194879.82 | CI8: 199568.34 | CJ8: 195803.52 | CK8: 183300.27 | CL8: 197029.26 | CM8: 172415.02 | CN8: 210226.66 | CO8: 205551.14 | CP8: 218773.41 | CQ8: 235846.61 | CR8: 206631.75 | CS8: 221718.5 | CT8: 230111.47 | CU8: 235436.57 | CV8: 227967.45 | CW8: 245276.62 | CX8: 206461.05 | CY8: 233543.09 | CZ8: 235413.98 | DA8: 271873.71 | DB8: 253178.1 | DC8: 248638.54 | DD8: 244865.41 | DE8: 202537.42
A9: 500A9 | CJ9: 114078.9 | CK9: 164358.66 | CL9: 135670.76 | CM9: 160283.53 | CN9: 177793.06 | CO9: 161036.69 | CP9: 194796.53 | CQ9: 176396.33 | CR9: 171695.77 | CS9: 190048.01 | CT9: 189928.55 | CU9: 207196.67 | CV9: 200204.54 | CW9: 161908.51 | CX9: 210818.66 | CY9: 227107.24 | CZ9: 222331.84 | DA9: 293910.75 | DB9: 279441.32 | DC9: 281701.81 | DD9: 320179.63 | DE9: 201947.04
A10: 500D4 | CA10: 107238.14 | CB10: 114128.89 | CC10: 129323.21 | CD10: 123750.08 | CE10: 131176.14 | CF10: 125240.71 | CG10: 129284.36 | CH10: 141262.31 | CI10: 143678.62 | CJ10: 148219.3 | CK10: 142200.34 | CL10: 131677.27 | CM10: 131557.68 | CN10: 148080.96 | CO10: 140917.48 | CP10: 156665.82 | CQ10: 142310.44 | CR10: 144614.62 | CS10: 147306.41 | CT10: 151463.37 | CU10: 150869.37 | CV10: 147642.4 | CW10: 135419.79 | CX10: 143252.23 | CY10: 164923.3 | CZ10: 156850.3 | DA10: 188341.37 | DB10: 160249.25 | DC10: 165807.31 | DD10: 165247.04 | DE10: 143623.28
A11: 500DU | CC11: 24871.007 | CD11: 153230.83 | CE11: 182793.1 | CF11: 178884.52 | CG11: 200416.46 | CH11: 183272.96 | CI11: 181430.41 | CJ11: 178115.84 | CK11: 155672.88 | CL11: 172746.93 | CM11: 159685.58 | CN11: 169570.62 | CO11: 160220.31 | CP11: 174903.03 | CQ11: 176470.58 | CR11: 178174.74 | CS11: 178007.49 | CT11: 178069.58 | CU11: 195585.43 | CV11: 182605.21 | CW11: 202282.68 | CX11: 202989.71 | CY11: 207705.57 | CZ11: 184818.22 | DA11: 213160.65 | DB11: 191609.84 | DC11: 197453.08 | DD11: 202683.25 | DE11: 177408.23
A12: 500E2 | BW12: 4662.265 | BX12: 125649.25 | BY12: 130288.21 | BZ12: 142021.17 | CA12: 162277.15 | CB12: 150360.78 | CC12: 200222.58 | CD12: 172431.94 | CE12: 182770.3 | CF12: 182938.85 | CG12: 190993.34 | CH12: 188955.26 | CI12: 194591.23 | CJ12: 193533.05 | CK12: 221926.96 | CL12: 210366.89 | CM12: 167307.47 | CN12: 190983.47 | CO12: 192360.33 | CP12: 203919.11 | CQ12: 209477.22 | CR12: 216117.85 | CS12: 226459.03 | CT12: 209281.56 | CU12: 217987.67 | CV12: 212096.59 | CW12: 227914.78 | CX12: 198374.95 | CY12: 210230.82 | CZ12: 194039.16 | DA12: 206644.85 | DB12: 204492.04 | DC12: 203435.58 | DD12: 62530.599 | DE12: 182577.71
A13: 500EZ | AG13: 68487.677 | AH13: 149361.4 | AI13: 174304.01 | AJ13: 187006.81 | AK13: 154580.92 | AL13: 79700.254 | AM13: 98108.449 | AN13: 124392.84 | AO13: 141868.59 | AP13: 139039.94 | AQ13: 165688.17 | AR13: 178379.08 | AS13: 178327.26 | AT13: 151065.42 | AU13: 182933.31 | AV13: 204110.55 | AW13: 177507.47 | AX13: 206251.06 | AY13: 213692.9 | AZ13: 226793.65 | BA13: 220256.73 | BB13: 234097.22 | BC13: 247325 | BD13: 251894.92 | BE13: 247496.87 | BF13: 243757.97 | BG13: 276137.87 | BH13: 253508.94 | BI13: 271323.82 | BJ13: 266730.33 | BK13: 277241.36 | BL13: 273287.21 | BM13: 284702.63 | BN13: 271479.03 | BO13: 262321.8 | BP13: 238905.61 | BQ13: 240799.14 | BR13: 263610.32 | BS13: 242163.73 | BT13: 250279.72 | BU13: 244480.49 | BV13: 248801.2 | BW13: 237669.85 | BX13: 260128.46 | BY13: 224690.01 | BZ13: 229947.77 | CA13: 230494.12 | CB13: 227468.95 | CC13: 236416.75 | CD13: 224007.03 | CE13: 240819.11 | CF13: 245449.01 | CG13: 259111.11 | CH13: 267259.69 | CI13: 266133.37 | CJ13: 276380.33 | CK13: 270483.58 | CL13: 263334.41 | CM13: 260663.12 | CN13: 277754.81 | CO13: 260112.92 | CP13: 275445.9 | CQ13: 265077.16 | CR13: 281995.65 | CS13: 276805.88 | CT13: 280306.69 | CU13: 283014.78 | CV13: 260785.15 | CW13: 249512.44 | CX13: 241364.94 | CY13: 271245.05 | CZ13: 251183.79 | DA13: 284157.01 | DB13: 269734.7 | DC13: 271519.59 | DD13: 244645.55 | DE13: 231280.53
A14: 500GV | CT14: 4168.7846 | CU14: 115449.47 | CV14: 133040.36 | CW14: 147083.65 | CX14: 123879.5 | CY14: 153360.86 | CZ14: 166911.66 | DA14: 202898.05 | DB14: 183338.04 | DC14: 179954.76 | DD14: 197691.66 | DE14: 146161.53
A15: 500TU | BU15: 20011.482 | BV15: 109106.42 | BW15: 116643.91 | BX15: 108853.08 | BY15: 122619.3 | BZ15: 127519.2 | CA15: 112262.48 | CB15: 123904.95 | CC15: 135707 | CD15: 120680.09 | CE15: 126049.38 | CF15: 120470.76 | CG15: 108217.94 | CH15: 139466.05 | CI15: 146164.09 | CJ15: 166687.26 | CK15: 180443.8 | CL15: 170618.25 | CM15: 174744.92 | CN15: 213293.45 | CO15: 190074.42 | CP15: 220307.31 | CQ15: 212999.38 | CR15: 196251.39 | CS15: 221776.04 | CT15: 218797.89 | CU15: 225907.73 | CV15: 224423.94 | CW15: 213096.94 | CX15: 210779.66 | CY15: 245758.87 | CZ15: 252417.28 | DA15: 274470.46 | DB15: 259570.47 | DC15: 264839.41 | DD15: 272910.75 | DE15: 176329.05
A16: 500WO | CL16: 128363.14 | CM16: 130180.16 | CN16: 169604.79 | CO16: 172515.19 | CP16: 196092.96 | CQ16: 184880.15 | CR16: 167320.47 | CS16: 191208.88 | CT16: 191643.76 | CU16: 190925.52 | CV16: 193549.17 | CW16: 186393.45 | CX16: 189138.84 | CY16: 214988.72 | CZ16: 220529.67 | DA16: 247422 | DB16: 204476.26 | DC16: 217850.69 | DD16: 224122.54 | DE16: 190589.81
A17: 500XK | BN17: 103365.89 | BO17: 148877.73 | BP17: 143467.52 | BQ17: 152084 | BR17: 158969.41 | BS17: 148548.28 | BT17: 150078.32 | BU17: 160103.16 | BV17: 155679.58 | BW17: 160966.25 | BX17: 161281.26 | BY17: 147601.67 | BZ17: 155420.81 | CA17: 149414.91 | CB17: 151349.22 | CC17: 172776.13 | CD17: 160011.8 | CE17: 169246.88 | CF17: 163851.57 | CG17: 183225.85 | CH17: 187673.54 | CI17: 173247.74 | CJ17: 184623.07 | CK17: 178484.92 | CL17: 174751.57 | CM17: 169978.91 | CN17: 186817.96 | CO17: 176513.44 | CP17: 189185.47 | CQ17: 173762.38 | CR17: 187895.59 | CS17: 193075.39 | CT17: 194212.99 | CU17: 202798.52 | CV17: 193496.78 | CW17: 179904.98 | CX17: 175191.12 | CY17: 205193.27 | CZ17: 190145.72 | DA17: 210567.52 | DB17: 203010.61 | DC17: 215997.44 | DD17: 204906.11 | DE17: 173203.61
A18: 5015G | BY18: 7934.4645 | BZ18: 151284.17 | CA18: 234889.97 | CB18: 126584.43 | CC18: 229708.21 | CD18: 109780.37 | CE18: 128348.23 | CF18: 256467.77 | CG18: 182064.67 | CH18: 228660.03 | CI18: 162778.67 | CJ18: 213185.79 | CK18: 213401.5 | CL18: 287713.12 | CM18: 157057.99 | CN18: 204029.41 | CO18: 277257.37 | CP18: 214172.08 | CQ18: 362498.1 | CR18: 248090.55 | CS18: 313488.36 | CT18: 228600.6 | CU18: 318624.36 | CV18: 294322.06 | CW18: 420850.09 | CX18: 186297.34 | CY18: 291684.78 | CZ18: 288845.32 | DA18: 300024.85 | DB18: 384743.27 | DC18: 328299.01 | DD18: 343769.78 | DE18: 240483.02
A19: 5015P | CD19: 35310.728 | CE19: 147774 | CF19: 157089.76 | CG19: 160397.82 | CH19: 167896.88 | CI19: 174215.6 | CJ19: 183250.71 | CK19: 189296.71 | CL19: 171151.63 | CM19: 150754.59 | CN19: 181747.48 | CO19: 178324.04 | CP19: 186140.39 | CQ19: 204679.09 | CR19: 191204.21 | CS19: 204587.14 | CT19: 185500.2 | CU19: 213552.94 | CV19: 205571.52 | CW19: 205197.68 | CX19: 180622.85 | CY19: 207091.79 | CZ19: 220003 | DA19: 276384.95 | DB19: 227610.13 | DC19: 223666.3 | DD19: 246171.3 | DE19: 187970.13
A20: 50162 | CI20: 5358.7767 | CJ20: 149928.42 | CK20: 159083.79 | CL20: 183018.39 | CM20: 179122.84 | CN20: 203930.32 | CO20: 183904.11 | CP20: 191349.25 | CQ20: 197697.5 | CR20: 194227.32 | CS20: 223224.25 | CT20: 222716.08 | CU20: 236298.11 | CV20: 236783.72 | CW20: 262939.49 | CX20: 247209.19 | CY20: 264157.84 | CZ20: 255543.02 | DA20: 310940.79 | DB20: 295887.25 | DC20: 286465.03 | DD20: 301174.18 | DE20: 217770.89
